Workbook
Name p_moneda: PARAMETROS!$B$6
Name p_horas_jornada: PARAMETROS!$B$7
Name p_factor_productividad: PARAMETROS!$B$8
Name p_dias_backlog_max: PARAMETROS!$B$11
Name p_dias_backlog_min: PARAMETROS!$B$12
Name p_meta_adherencia: PARAMETROS!$B$13
Name p_meta_ratio_prev_corr: PARAMETROS!$B$14
Name p_ruta_base_checklists: PARAMETROS!$B$16
Name lista_turnos: PARAMETROS!$E$5:$E$10
Name lista_no_disponible: PARAMETROS!$G$5:$G$6
Name lista_dias: PARAMETROS!$I$5:$I$11
Name lista_tecnicos: TECNICOS!$B$4:$B$15

Sheet INICIO
A1: MantPlan — Planificador semanal de mantenimiento
A2: Versión 2.0.0 · generado 2026-07-20 · datos 100 % sintéticos de ejemplo
A4: PRINCIPIO RECTOR — separación entre lógica y datos:
A5: · MOTOR: las 10 reglas de negocio viven en las fórmulas de este libro y nunca cambian.
A6: · CATÁLOGOS: centros de costo, puestos, actividades, tipos de OT y estados se cargan por empresa.
A7: · PARÁMETROS: jornada, productividad, ventanas de backlog y metas se ajustan en PARAMETROS.
A8: · No hay macros, ni enlaces externos, ni códigos de empresa dentro de ninguna fórmula.
A10: FLUJO DE USO EN 5 PASOS:
A11: 1. Ajuste PARAMETROS y cargue los catálogos de su empresa (hojas CAT_*).
A12: 2. Pegue la exportación de órdenes (12 columnas, en este orden) directamente en ORDENES!A4:
A13: un solo bloque contiguo A:L. Hay 1.200 filas provisionadas con las fórmulas ya escritas.
A14: 3. Pegue la segunda exportación (estados y costos) en 2_IMPORTAR_EJECUCION.
... A24: · PLAN_SEMANAL: el gráfico de carga por técnico responde a los mismos selectores que la grilla.

Sheet PARAMETROS
A1: PARÁMETROS DEL MOTOR (Tabla 10)
A3: parametro | B3: valor | C3: descripcion | E3: listas auxiliares
A4: nombre_empresa | B4: Empresa Ejemplo S.A. | C4: Editable. Solo informativo, no participa en cálculos. | E4: turnos y códigos de ausencia: | G4: no disponible: | I4: días (1 = lunes):
A5: nombre_planta | B5: Planta Ejemplo | C5: Editable. Solo informativo. | E5: B1 | G5: VAC | I5: lunes
A6: moneda | B6: USD | C6: Moneda de los costos. | E6: T1 | G6: X | I6: martes
A7: horas_jornada | B7: 7 | C7: Horas de trabajo por técnico y día (REGLA-5). | E7: T2 | I7: miércoles
A8: factor_productividad | B8: 0.87 | C8: Fracción productiva de la jornada (REGLA-6). | E8: T3 | I8: jueves
A9: turnos | B9: B1,T1,T2,T3 | C9: Códigos de turno válidos (lista auxiliar a la derecha). | E9: VAC | I9: viernes
A10: codigos_no_disponible | B10: VAC,X | C10: Códigos que anulan la disponibilidad (REGLA-5). | E10: X | I10: sábado
A11: dias_backlog_max | B11: 30 | C11: Días hacia atrás que siguen siendo plan (REGLAS 3 y 4). | I11: domingo
A12: dias_backlog_min | B12: -92 | C12: Días hacia adelante (negativo) que entran al plan (REGLA-4).
A13: meta_adherencia | B13: 0.95 | C13: Meta de adherencia semanal (REGLA-7).
A14: meta_ratio_prev_corr | B14: 0.8 | C14: Meta: fracción preventiva mínima de las HH (REGLA-9).
A15: primer_dia_semana | B15: lunes | C15: Inicio de semana. La semana ISO (REGLA-2) empieza en lunes.
A16: ruta_base_checklists | B16: C:\MANTPLAN\checklists\ | C16: Base para los hipervínculos de la columna link_checklist.

Sheet 1_IMPORTAR_ORDENES
A1: ZONA DE PEGADO — exportación de órdenes del ERP
A3: Ordene la exportación de su ERP con estas 12 cabeceras exactas (misma disposición que ORDENES!A:L)
A4: y péguela EN UN SOLO PASO en ORDENES!A4 (o desde la primera fila libre). Nada más que hacer:
A5: las columnas calculadas ya están escritas en las 1.200 filas provisionadas de la tabla.
A6: operacion es opcional: si su ERP no maneja operaciones, déjela vacía y el sistema asume "0010".
A7: horas_ajustadas (columna M de ORDENES) es del planificador y NO se pega: sobrevive a la re-importación.
A8: orden | B8: operacion | C8: descripcion_general | D8: descripcion_operacion | E8: equipo | F8: centro_costo | G8: puesto_trabajo | H8: cod_actividad | I8: tipo_ot | J8: fecha_inicio | K8: horas_estimadas | L8: costo_plan
A9: OT-000001 | B9: 0010 | C9: Lubricación programada — EQ-102 | D9: Lubricación programada en EQ-102 | E9: EQ-102 | F9: CC-110 | G9: PU-MEC | H9: ACT-02 | I9: TIPO-P2 | J9: 46216 | K9: 10 | L9: 250
A10: OT-000002 | B10: 0010 | C10: Análisis predictivo — EQ-108 | D10: Análisis predictivo en EQ-108 | E10: EQ-108 | F10: CC-210 | G10: PU-MEC | H10: ACT-04 | I10: TIPO-P1 | J10: 46217 | K10: 8 | L10: 200

Sheet 2_IMPORTAR_EJECUCION
A1: ZONA DE PEGADO — segunda exportación: estados y costos (tblEjecucion)
A3: Pegue aquí los estados y costos reales del ERP, con estas cabeceras exactas, desde la primera fila vacía.
A4: id_operacion se calcula solo. El catálogo CAT_ESTADOS_ERP traduce estado_sistema a Cerrada/Pendiente.
A5: Las órdenes sin par en esta tabla quedan como "Pendiente" (REGLA-10).
A8: orden | B8: operacion | C8: estado_sistema | D8: prioridad | E8: estado_instalacion | F8: precio | G8: costo_real | H8: costo_plan_total | I8: estado_usuario | J8: id_operacion
A9: OT-000001 | B9: 0010 | C9: LIB | D9: 1-ALTA | E9: OPERATIVO | F9: 100 | G9: 0 | H9: 250 | I9: LIBERADA | J9: =IF(tblEjecucion[[#This Row],[orden]]="","",tblEjecucion[[#This Row],[orden]]&IF(tblEjecucion[[#This Row],[operacion]]="","0010",tblEjecucion[[#This Row],[operacion]]))
A10: OT-000002 | B10: 0010 | C10: CERR | D10: 2-MEDIA | E10: PARADO | F10: 80 | G10: 200 | H10: 200 | I10: CERRADA | J10: =IF(tblEjecucion[[#This Row],[orden]]="","",tblEjecucion[[#This Row],[orden]]&IF(tblEjecucion[[#This Row],[operacion]]="","0010",tblEjecucion[[#This Row],[operacion]]))
A11: OT-000003 | B11: 0010 | C11: CERR | D11: 3-BAJA | E11: OPERATIVO | F11: 60 | G11: 150 | H11: 150 | I11: CERRADA | J11: =IF(tblEjecucion[[#This Row],[orden]]="","",tblEjecucion[[#This Row],[orden]]&IF(tblEjecucion[[#This Row],[operacion]]="","0010",tblEjecucion[[#This Row],[operacion]]))
A12: OT-000004 | B12: 0010 | C12: CERR | D12: 1-ALTA | E12: PARADO | F12: 100 | G12: 250 | H12: 250 | I12: CERRADA | J12: =IF(tblEjecucion[[#This Row],[orden]]="","",tblEjecucion[[#This Row],[orden]]&IF(tblEjecucion[[#This Row],[operacion]]="","0010",tblEjecucion[[#This Row],[operacion]]))
A13: OT-000005 | B13: 0010 | C13: CERR | D13: 2-MEDIA | E13: OPERATIVO | F13: 80 | G13: 200 | H13: 200 | I13: CERRADA | J13: =IF(tblEjecucion[[#This Row],[orden]]="","",tblEjecucion[[#This Row],[orden]]&IF(tblEjecucion[[#This Row],[operacion]]="","0010",tblEjecucion[[#This Row],[operacion]]))
A14: OT-000006 | B14: 0010 | C14: CERR | D14: 3-BAJA | E14: PARADO | F14: 60 | G14: 150 | H14: 150 | I14: CERRADA | J14: =IF(tblEjecucion[[#This Row],[orden]]="","",tblEjecucion[[#This Row],[orden]]&IF(tblEjecucion[[#This Row],[operacion]]="","0010",tblEjecucion[[#This Row],[operacion]]))
A15: OT-000007 | B15: 0010 | C15: CERR | D15: 1-ALTA | E15: OPERATIVO | F15: 100 | G15: 250 | H15: 250 | I15: CERRADA | J15: =IF(tblEjecucion[[#This Row],[orden]]="","",tblEjecucion[[#This Row],[orden]]&IF(tblEjecucion[[#This Row],[operacion]]="","0010",tblEjecucion[[#This Row],[operacion]]))
A16: OT-000008 | B16: 0010 | C16: CERR | D16: 2-MEDIA | E16: PARADO | F16: 80 | G16: 200 | H16: 200 | I16: CERRADA | J16: =IF(tblEjecucion[[#This Row],[orden]]="","",tblEjecucion[[#This Row],[orden]]&IF(tblEjecucion[[#This Row],[operacion]]="","0010",tblEjecucion[[#This Row],[operacion]]))
A17: OT-000009 | B17: 0010 | C17: CERR | D17: 3-BAJA | E17: OPERATIVO | F17: 60 | G17: 150 | H17: 150 | I17: CERRADA | J17: =IF(tblEjecucion[[#This Row],[orden]]="","",tblEjecucion[[#This Row],[orden]]&IF(tblEjecucion[[#This Row],[operacion]]="","0010",tblEjecucion[[#This Row],[operacion]]))
A18: OT-000010 | B18: 0010 | C18: CERR | D18: 1-ALTA | E18: PARADO | F18: 80 | G18: 200 | H18: 200 | I18: CERRADA | J18: =IF(tblEjecucion[[#This Row],[orden]]="","",tblEjecucion[[#This Row],[orden]]&IF(tblEjecucion[[#This Row],[operacion]]="","0010",tblEjecucion[[#This Row],[operacion]]))
A19: OT-000011 | B19: 0010 | C19: CERR | D19: 2-MEDIA | E19: OPERATIVO | F19: 160 | G19: 400 | H19: 400 | I19: CERRADA | J19: =IF(tblEjecucion[[#This Row],[orden]]="","",tblEjecucion[[#This Row],[orden]]&IF(tblEjecucion[[#This Row],[operacion]]="","0010",tblEjecucion[[#This Row],[operacion]]))
A20: OT-000012 | B20: 0010 | C20: CERR | D20: 3-BAJA | E20: PARADO | F20: 160 | G20: 400 | H20: 400 | I20: CERRADA | J20: =IF(tblEjecucion[[#This Row],[orden]]="","",tblEjecucion[[#This Row],[orden]]&IF(tblEjecucion[[#This Row],[operacion]]="","0010",tblEjecucion[[#This Row],[operacion]]))
... A169: OT-000992 | B169: 0010 | C169: LIB | D169: 2-MEDIA | E169: OPERATIVO | F169: 50 | G169: 0 | H169: 150 | I169: LIBERADA | J169: =IF(tblEjecucion[[#This Row],[orden]]="","",tblEjecucion[[#This Row],[orden]]&IF(tblEjecucion[[#This Row],[operacion]]="","0010",tblEjecucion[[#This Row],[operacion]]))
J170: =IF(tblEjecucion[[#This Row],[orden]]="","",tblEjecucion[[#This Row],[orden]]&IF(tblEjecucion[[#This Row],[operacion]]="","0010",tblEjecucion[[#This Row],[operacion]]))
J171: =IF(tblEjecucion[[#This Row],[orden]]="","",tblEjecucion[[#This Row],[orden]]&IF(tblEjecucion[[#This Row],[operacion]]="","0010",tblEjecucion[[#This Row],[operacion]]))
J172: =IF(tblEjecucion[[#This Row],[orden]]="","",tblEjecucion[[#This Row],[orden]]&IF(tblEjecucion[[#This Row],[operacion]]="","0010",tblEjecucion[[#This Row],[operacion]]))
J173: =IF(tblEjecucion[[#This Row],[orden]]="","",tblEjecucion[[#This Row],[orden]]&IF(tblEjecucion[[#This Row],[operacion]]="","0010",tblEjecucion[[#This Row],[operacion]]))
J174: =IF(tblEjecucion[[#This Row],[orden]]="","",tblEjecucion[[#This Row],[orden]]&IF(tblEjecucion[[#This Row],[operacion]]="","0010",tblEjecucion[[#This Row],[operacion]]))
J175: =IF(tblEjecucion[[#This Row],[orden]]="","",tblEjecucion[[#This Row],[orden]]&IF(tblEjecucion[[#This Row],[operacion]]="","0010",tblEjecucion[[#This Row],[operacion]]))
J176: =IF(tblEjecucion[[#This Row],[orden]]="","",tblEjecucion[[#This Row],[orden]]&IF(tblEjecucion[[#This Row],[operacion]]="","0010",tblEjecucion[[#This Row],[operacion]]))
J177: =IF(tblEjecucion[[#This Row],[orden]]="","",tblEjecucion[[#This Row],[orden]]&IF(tblEjecucion[[#This Row],[operacion]]="","0010",tblEjecucion[[#This Row],[operacion]]))
J178: =IF(tblEjecucion[[#This Row],[orden]]="","",tblEjecucion[[#This Row],[orden]]&IF(tblEjecucion[[#This Row],[operacion]]="","0010",tblEjecucion[[#This Row],[operacion]]))
J179: =IF(tblEjecucion[[#This Row],[orden]]="","",tblEjecucion[[#This Row],[orden]]&IF(tblEjecucion[[#This Row],[operacion]]="","0010",tblEjecucion[[#This Row],[operacion]]))
J180: =IF(tblEjecucion[[#This Row],[orden]]="","",tblEjecucion[[#This Row],[orden]]&IF(tblEjecucion[[#This Row],[operacion]]="","0010",tblEjecucion[[#This Row],[operacion]]))
J181: =IF(tblEjecucion[[#This Row],[orden]]="","",tblEjecucion[[#This Row],[orden]]&IF(tblEjecucion[[#This Row],[operacion]]="","0010",tblEjecucion[[#This Row],[operacion]]))
... J1208: =IF(tblEjecucion[[#This Row],[orden]]="","",tblEjecucion[[#This Row],[orden]]&IF(tblEjecucion[[#This Row],[operacion]]="","0010",tblEjecucion[[#This Row],[operacion]]))

Sheet ORDENES
A1: ORDENES — tabla madre (tblOrdenes). Azul = editable; el resto se calcula solo.
A3: orden | B3: operacion | C3: descripcion_general | D3: descripcion_operacion | E3: equipo | F3: centro_costo | G3: puesto_trabajo | H3: cod_actividad | I3: tipo_ot | J3: fecha_inicio | K3: horas_estimadas | L3: costo_plan | M3: horas_ajustadas | N3: horas_efectivas | O3: estado | P3: semana | Q3: anio | R3: mes | S3: dia_semana | T3: clasificacion | U3: linea | V3: area | W3: coordinador | X3: especialidad | Y3: actividad | Z3: backlog_dias | AA3: estado_backlog | AB3: en_plan | AC3: tecnico_asignado | AD3: turno_asignado | AE3: HHA | AF3: HHD | AG3: costo_servicio | AH3: costo_materiales | AI3: costo_total | AJ3: permiso_requerido | AK3: bloqueo_energia | AL3: link_checklist | AM3: abrir_checklist | AN3: observaciones | AO3: id_operacion
A4: OT-000001 | B4: 0010 | C4: Lubricación programada — EQ-102 | D4: Lubricación programada en EQ-102 | E4: EQ-102 | F4: CC-110 | G4: PU-MEC | H4: ACT-02 | I4: TIPO-P2 | J4: 46216 | K4: 10 | L4: 250 | N4: =IF(tblOrdenes[[#This Row],[orden]]="","",IF(tblOrdenes[[#This Row],[horas_ajustadas]]<>"",tblOrdenes[[#This Row],[horas_ajustadas]],IF(tblOrdenes[[#This Row],[horas_estimadas]]="","",tblOrdenes[[#This Row],[horas_estimadas]]))) | O4: =IF(tblOrdenes[[#This Row],[orden]]="","",_xlfn.XLOOKUP(_xlfn.XLOOKUP(tblOrdenes[[#This Row],[id_operacion]],tblEjecucion[id_operacion],tblEjecucion[estado_sistema],""),tblEstados[estado_sistema],tblEstados[estado_normalizado],"Pendiente")) | P4: =IF(tblOrdenes[[#This Row],[fecha_inicio]]="","",YEAR(tblOrdenes[[#This Row],[fecha_inicio]]+4-WEEKDAY(tblOrdenes[[#This Row],[fecha_inicio]],2))&"-S"&TEXT(_xlfn.ISOWEEKNUM(tblOrdenes[[#This Row],[fecha_inicio]]),"00")) | Q4: =IF(tblOrdenes[[#This Row],[fecha_inicio]]="","",YEAR(tblOrdenes[[#This Row],[fecha_inicio]])) | R4: =IF(tblOrdenes[[#This Row],[fecha_inicio]]="","",MONTH(tblOrdenes[[#This Row],[fecha_inicio]])) | S4: =IF(tblOrdenes[[#This Row],[fecha_inicio]]="","",INDEX(lista_dias,WEEKDAY(tblOrdenes[[#This Row],[fecha_inicio]],2))) | T4: =IF(tblOrdenes[[#This Row],[tipo_ot]]="","",_xlfn.XLOOKUP(tblOrdenes[[#This Row],[tipo_ot]],tblTiposOT[codigo],tblTiposOT[clasificacion],"sin_clasificar")) | U4: =IF(tblOrdenes[[#This Row],[centro_costo]]="","",_xlfn.XLOOKUP(tblOrdenes[[#This Row],[centro_costo]],tblCECO[codigo],tblCECO[linea],"(sin catálogo)")) | V4: =IF(tblOrdenes[[#This Row],[centro_costo]]="","",_xlfn.XLOOKUP(tblOrdenes[[#This Row],[centro_costo]],tblCECO[codigo],tblCECO[area],"(sin catálogo)")) | W4: =IF(tblOrdenes[[#This Row],[centro_costo]]="","",_xlfn.XLOOKUP(tblOrdenes[[#This Row],[centro_costo]],tblCECO[codigo],tblCECO[coordinador],"(sin catálogo)")) | X4: =IF(tblOrdenes[[#This Row],[puesto_trabajo]]="","",_xlfn.XLOOKUP(tblOrdenes[[#This Row],[puesto_trabajo]],tblPuestos[codigo],tblPuestos[especialidad],"(sin catálogo)")) | Y4: =IF(tblOrdenes[[#This Row],[cod_actividad]]="","",_xlfn.XLOOKUP(tblOrdenes[[#This Row],[cod_actividad]],tblActividades[codigo],tblActividades[descripcion],"(sin catálogo)")) | Z4: =IF(tblOrdenes[[#This Row],[fecha_inicio]]="","",TODAY()-tblOrdenes[[#This Row],[fecha_inicio]]) | AA4: =IF(tblOrdenes[[#This Row],[backlog_dias]]="","",IF(tblOrdenes[[#This Row],[backlog_dias]]<0,"FUTURO",IF(tblOrdenes[[#This Row],[backlog_dias]]>p_dias_backlog_max,"BACKLOG","MES CORRIENTE"))) | AB4: =IF(tblOrdenes[[#This Row],[backlog_dias]]="",FALSE,AND(tblOrdenes[[#This Row],[backlog_dias]]>p_dias_backlog_min,tblOrdenes[[#This Row],[backlog_dias]]<=p_dias_backlog_max)) | AC4: Técnico 01 | AD4: =IF(tblOrdenes[[#This Row],[tecnico_asignado]]="","",_xlfn.XLOOKUP(tblOrdenes[[#This Row],[semana]]&"|"&tblOrdenes[[#This Row],[dia_semana]]&"|"&tblOrdenes[[#This Row],[tecnico_asignado]],tblAsignaciones[clave],tblAsignaciones[turno],"")) | AE4: =IF(tblOrdenes[[#This Row],[tecnico_asignado]]="","",SUMIFS(tblOrdenes[horas_efectivas],tblOrdenes[tecnico_asignado],tblOrdenes[[#This Row],[tecnico_asignado]],tblOrdenes[semana],tblOrdenes[[#This Row],[semana]],tblOrdenes[dia_semana],tblOrdenes[[#This Row],[dia_semana]])) | AF4: =IF(tblOrdenes[[#This Row],[HHA]]="","",p_factor_productividad*_xlfn.XLOOKUP(tblOrdenes[[#This Row],[semana]]&"|"&tblOrdenes[[#This Row],[dia_semana]]&"|"&tblOrdenes[[#This Row],[tecnico_asignado]],tblAsignaciones[clave],tblAsignaciones[horas_disponibles],0)-tblOrdenes[[#This Row],[HHA]]) | AG4: =IF(tblOrdenes[[#This Row],[orden]]="","",_xlfn.XLOOKUP(tblOrdenes[[#This Row],[id_operacion]],tblEjecucion[id_operacion],tblEjecucion[precio],0)) | AH4: =IF(tblOrdenes[[#This Row],[orden]]="","",MAX(0,_xlfn.XLOOKUP(tblOrdenes[[#This Row],[id_operacion]],tblEjecucion[id_operacion],tblEjecucion[costo_plan_total],0)-tblOrdenes[[#This Row],[costo_servicio]])) | AI4: =IF(tblOrdenes[[#This Row],[orden]]="","",tblOrdenes[[#This Row],[costo_servicio]]+tblOrdenes[[#This Row],[costo_materiales]]) | AL4: ACT-02.pdf | AM4: =IF(tblOrdenes[[#This Row],[link_checklist]]="","",HYPERLINK(p_ruta_base_checklists&tblOrdenes[[#This Row],[link_checklist]],"abrir")) | AO4: =IF(tblOrdenes[[#This Row],[orden]]="","",tblOrdenes[[#This Row],[orden]]&IF(tblOrdenes[[#This Row],[operacion]]="","0010",tblOrdenes[[#This Row],[operacion]]))
A5: OT-000002 | B5: 0010 | C5: Análisis predictivo — EQ-108 | D5: Análisis predictivo en EQ-108 | E5: EQ-108 | F5: CC-210 | G5: PU-MEC | H5: ACT-04 | I5: TIPO-P1 | J5: 46217 | K5: 8 | L5: 200 | N5: =IF(tblOrdenes[[#This Row],[orden]]="","",IF(tblOrdenes[[#This Row],[horas_ajustadas]]<>"",tblOrdenes[[#This Row],[horas_ajustadas]],IF(tblOrdenes[[#This Row],[horas_estimadas]]="","",tblOrdenes[[#This Row],[horas_estimadas]]))) | O5: =IF(tblOrdenes[[#This Row],[orden]]="","",_xlfn.XLOOKUP(_xlfn.XLOOKUP(tblOrdenes[[#This Row],[id_operacion]],tblEjecucion[id_operacion],tblEjecucion[estado_sistema],""),tblEstados[estado_sistema],tblEstados[estado_normalizado],"Pendiente")) | P5: =IF(tblOrdenes[[#This Row],[fecha_inicio]]="","",YEAR(tblOrdenes[[#This Row],[fecha_inicio]]+4-WEEKDAY(tblOrdenes[[#This Row],[fecha_inicio]],2))&"-S"&TEXT(_xlfn.ISOWEEKNUM(tblOrdenes[[#This Row],[fecha_inicio]]),"00")) | Q5: =IF(tblOrdenes[[#This Row],[fecha_inicio]]="","",YEAR(tblOrdenes[[#This Row],[fecha_inicio]])) | R5: =IF(tblOrdenes[[#This Row],[fecha_inicio]]="","",MONTH(tblOrdenes[[#This Row],[fecha_inicio]])) | S5: =IF(tblOrdenes[[#This Row],[fecha_inicio]]="","",INDEX(lista_dias,WEEKDAY(tblOrdenes[[#This Row],[fecha_inicio]],2))) | T5: =IF(tblOrdenes[[#This Row],[tipo_ot]]="","",_xlfn.XLOOKUP(tblOrdenes[[#This Row],[tipo_ot]],tblTiposOT[codigo],tblTiposOT[clasificacion],"sin_clasificar")) | U5: =IF(tblOrdenes[[#This Row],[centro_costo]]="","",_xlfn.XLOOKUP(tblOrdenes[[#This Row],[centro_costo]],tblCECO[codigo],tblCECO[linea],"(sin catálogo)")) | V5: =IF(tblOrdenes[[#This Row],[centro_costo]]="","",_xlfn.XLOOKUP(tblOrdenes[[#This Row],[centro_costo]],tblCECO[codigo],tblCECO[area],"(sin catálogo)")) | W5: =IF(tblOrdenes[[#This Row],[centro_costo]]="","",_xlfn.XLOOKUP(tblOrdenes[[#This Row],[centro_costo]],tblCECO[codigo],tblCECO[coordinador],"(sin catálogo)")) | X5: =IF(tblOrdenes[[#This Row],[puesto_trabajo]]="","",_xlfn.XLOOKUP(tblOrdenes[[#This Row],[puesto_trabajo]],tblPuestos[codigo],tblPuestos[especialidad],"(sin catálogo)")) | Y5: =IF(tblOrdenes[[#This Row],[cod_actividad]]="","",_xlfn.XLOOKUP(tblOrdenes[[#This Row],[cod_actividad]],tblActividades[codigo],tblActividades[descripcion],"(sin catálogo)")) | Z5: =IF(tblOrdenes[[#This Row],[fecha_inicio]]="","",TODAY()-tblOrdenes[[#This Row],[fecha_inicio]]) | AA5: =IF(tblOrdenes[[#This Row],[backlog_dias]]="","",IF(tblOrdenes[[#This Row],[backlog_dias]]<0,"FUTURO",IF(tblOrdenes[[#This Row],[backlog_dias]]>p_dias_backlog_max,"BACKLOG","MES CORRIENTE"))) | AB5: =IF(tblOrdenes[[#This Row],[backlog_dias]]="",FALSE,AND(tblOrdenes[[#This Row],[backlog_dias]]>p_dias_backlog_min,tblOrdenes[[#This Row],[backlog_dias]]<=p_dias_backlog_max)) | AC5: Técnico 02 | AD5: =IF(tblOrdenes[[#This Row],[tecnico_asignado]]="","",_xlfn.XLOOKUP(tblOrdenes[[#This Row],[semana]]&"|"&tblOrdenes[[#This Row],[dia_semana]]&"|"&tblOrdenes[[#This Row],[tecnico_asignado]],tblAsignaciones[clave],tblAsignaciones[turno],"")) | AE5: =IF(tblOrdenes[[#This Row],[tecnico_asignado]]="","",SUMIFS(tblOrdenes[horas_efectivas],tblOrdenes[tecnico_asignado],tblOrdenes[[#This Row],[tecnico_asignado]],tblOrdenes[semana],tblOrdenes[[#This Row],[semana]],tblOrdenes[dia_semana],tblOrdenes[[#This Row],[dia_semana]])) | AF5: =IF(tblOrdenes[[#This Row],[HHA]]="","",p_factor_productividad*_xlfn.XLOOKUP(tblOrdenes[[#This Row],[semana]]&"|"&tblOrdenes[[#This Row],[dia_semana]]&"|"&tblOrdenes[[#This Row],[tecnico_asignado]],tblAsignaciones[clave],tblAsignaciones[horas_disponibles],0)-tblOrdenes[[#This Row],[HHA]]) | AG5: =IF(tblOrdenes[[#This Row],[orden]]="","",_xlfn.XLOOKUP(tblOrdenes[[#This Row],[id_operacion]],tblEjecucion[id_operacion],tblEjecucion[precio],0)) | AH5: =IF(tblOrdenes[[#This Row],[orden]]="","",MAX(0,_xlfn.XLOOKUP(tblOrdenes[[#This Row],[id_operacion]],tblEjecucion[id_operacion],tblEjecucion[costo_plan_total],0)-tblOrdenes[[#This Row],[costo_servicio]])) | AI5: =IF(tblOrdenes[[#This Row],[orden]]="","",tblOrdenes[[#This Row],[costo_servicio]]+tblOrdenes[[#This Row],[costo_materiales]]) | AL5: ACT-04.pdf | AM5: =IF(tblOrdenes[[#This Row],[link_checklist]]="","",HYPERLINK(p_ruta_base_checklists&tblOrdenes[[#This Row],[link_checklist]],"abrir")) | AO5: =IF(tblOrdenes[[#This Row],[orden]]="","",tblOrdenes[[#This Row],[orden]]&IF(tblOrdenes[[#This Row],[operacion]]="","0010",tblOrdenes[[#This Row],[operacion]]))
A6: OT-000003 | B6: 0010 | C6: Inspección de rutina — EQ-110 | D6: Inspección de rutina en EQ-110 | E6: EQ-110 | F6: CC-310 | G6: PU-MEC | H6: ACT-01 | I6: TIPO-P2 | J6: 46218 | K6: 6 | L6: 150 | N6: =IF(tblOrdenes[[#This Row],[orden]]="","",IF(tblOrdenes[[#This Row],[horas_ajustadas]]<>"",tblOrdenes[[#This Row],[horas_ajustadas]],IF(tblOrdenes[[#This Row],[horas_estimadas]]="","",tblOrdenes[[#This Row],[horas_estimadas]]))) | O6: =IF(tblOrdenes[[#This Row],[orden]]="","",_xlfn.XLOOKUP(_xlfn.XLOOKUP(tblOrdenes[[#This Row],[id_operacion]],tblEjecucion[id_operacion],tblEjecucion[estado_sistema],""),tblEstados[estado_sistema],tblEstados[estado_normalizado],"Pendiente")) | P6: =IF(tblOrdenes[[#This Row],[fecha_inicio]]="","",YEAR(tblOrdenes[[#This Row],[fecha_inicio]]+4-WEEKDAY(tblOrdenes[[#This Row],[fecha_inicio]],2))&"-S"&TEXT(_xlfn.ISOWEEKNUM(tblOrdenes[[#This Row],[fecha_inicio]]),"00")) | Q6: =IF(tblOrdenes[[#This Row],[fecha_inicio]]="","",YEAR(tblOrdenes[[#This Row],[fecha_inicio]])) | R6: =IF(tblOrdenes[[#This Row],[fecha_inicio]]="","",MONTH(tblOrdenes[[#This Row],[fecha_inicio]])) | S6: =IF(tblOrdenes[[#This Row],[fecha_inicio]]="","",INDEX(lista_dias,WEEKDAY(tblOrdenes[[#This Row],[fecha_inicio]],2))) | T6: =IF(tblOrdenes[[#This Row],[tipo_ot]]="","",_xlfn.XLOOKUP(tblOrdenes[[#This Row],[tipo_ot]],tblTiposOT[codigo],tblTiposOT[clasificacion],"sin_clasificar")) | U6: =IF(tblOrdenes[[#This Row],[centro_costo]]="","",_xlfn.XLOOKUP(tblOrdenes[[#This Row],[centro_costo]],tblCECO[codigo],tblCECO[linea],"(sin catálogo)")) | V6: =IF(tblOrdenes[[#This Row],[centro_costo]]="","",_xlfn.XLOOKUP(tblOrdenes[[#This Row],[centro_costo]],tblCECO[codigo],tblCECO[area],"(sin catálogo)")) | W6: =IF(tblOrdenes[[#This Row],[centro_costo]]="","",_xlfn.XLOOKUP(tblOrdenes[[#This Row],[centro_costo]],tblCECO[codigo],tblCECO[coordinador],"(sin catálogo)")) | X6: =IF(tblOrdenes[[#This Row],[puesto_trabajo]]="","",_xlfn.XLOOKUP(tblOrdenes[[#This Row],[puesto_trabajo]],tblPuestos[codigo],tblPuestos[especialidad],"(sin catálogo)")) | Y6: =IF(tblOrdenes[[#This Row],[cod_actividad]]="","",_xlfn.XLOOKUP(tblOrdenes[[#This Row],[cod_actividad]],tblActividades[codigo],tblActividades[descripcion],"(sin catálogo)")) | Z6: =IF(tblOrdenes[[#This Row],[fecha_inicio]]="","",TODAY()-tblOrdenes[[#This Row],[fecha_inicio]]) | AA6: =IF(tblOrdenes[[#This Row],[backlog_dias]]="","",IF(tblOrdenes[[#This Row],[backlog_dias]]<0,"FUTURO",IF(tblOrdenes[[#This Row],[backlog_dias]]>p_dias_backlog_max,"BACKLOG","MES CORRIENTE"))) | AB6: =IF(tblOrdenes[[#This Row],[backlog_dias]]="",FALSE,AND(tblOrdenes[[#This Row],[backlog_dias]]>p_dias_backlog_min,tblOrdenes[[#This Row],[backlog_dias]]<=p_dias_backlog_max)) | AC6: Técnico 03 | AD6: =IF(tblOrdenes[[#This Row],[tecnico_asignado]]="","",_xlfn.XLOOKUP(tblOrdenes[[#This Row],[semana]]&"|"&tblOrdenes[[#This Row],[dia_semana]]&"|"&tblOrdenes[[#This Row],[tecnico_asignado]],tblAsignaciones[clave],tblAsignaciones[turno],"")) | AE6: =IF(tblOrdenes[[#This Row],[tecnico_asignado]]="","",SUMIFS(tblOrdenes[horas_efectivas],tblOrdenes[tecnico_asignado],tblOrdenes[[#This Row],[tecnico_asignado]],tblOrdenes[semana],tblOrdenes[[#This Row],[semana]],tblOrdenes[dia_semana],tblOrdenes[[#This Row],[dia_semana]])) | AF6: =IF(tblOrdenes[[#This Row],[HHA]]="","",p_factor_productividad*_xlfn.XLOOKUP(tblOrdenes[[#This Row],[semana]]&"|"&tblOrdenes[[#This Row],[dia_semana]]&"|"&tblOrdenes[[#This Row],[tecnico_asignado]],tblAsignaciones[clave],tblAsignaciones[horas_disponibles],0)-tblOrdenes[[#This Row],[HHA]]) | AG6: =IF(tblOrdenes[[#This Row],[orden]]="","",_xlfn.XLOOKUP(tblOrdenes[[#This Row],[id_operacion]],tblEjecucion[id_operacion],tblEjecucion[precio],0)) | AH6: =IF(tblOrdenes[[#This Row],[orden]]="","",MAX(0,_xlfn.XLOOKUP(tblOrdenes[[#This Row],[id_operacion]],tblEjecucion[id_operacion],tblEjecucion[costo_plan_total],0)-tblOrdenes[[#This Row],[costo_servicio]])) | AI6: =IF(tblOrdenes[[#This Row],[orden]]="","",tblOrdenes[[#This Row],[costo_servicio]]+tblOrdenes[[#This Row],[costo_materiales]]) | AL6: ACT-01.pdf | AM6: =IF(tblOrdenes[[#This Row],[link_checklist]]="","",HYPERLINK(p_ruta_base_checklists&tblOrdenes[[#This Row],[link_checklist]],"abrir")) | AO6: =IF(tblOrdenes[[#This Row],[orden]]="","",tblOrdenes[[#This Row],[orden]]&IF(tblOrdenes[[#This Row],[operacion]]="","0010",tblOrdenes[[#This Row],[operacion]]))
A7: OT-000004 | B7: 0010 | C7: Lubricación programada — EQ-105 | D7: Lubricación programada en EQ-105 | E7: EQ-105 | F7: CC-110 | G7: PU-MEC | H7: ACT-02 | I7: TIPO-P1 | J7: 46219 | K7: 10 | L7: 250 | N7: =IF(tblOrdenes[[#This Row],[orden]]="","",IF(tblOrdenes[[#This Row],[horas_ajustadas]]<>"",tblOrdenes[[#This Row],[horas_ajustadas]],IF(tblOrdenes[[#This Row],[horas_estimadas]]="","",tblOrdenes[[#This Row],[horas_estimadas]]))) | O7: =IF(tblOrdenes[[#This Row],[orden]]="","",_xlfn.XLOOKUP(_xlfn.XLOOKUP(tblOrdenes[[#This Row],[id_operacion]],tblEjecucion[id_operacion],tblEjecucion[estado_sistema],""),tblEstados[estado_sistema],tblEstados[estado_normalizado],"Pendiente")) | P7: =IF(tblOrdenes[[#This Row],[fecha_inicio]]="","",YEAR(tblOrdenes[[#This Row],[fecha_inicio]]+4-WEEKDAY(tblOrdenes[[#This Row],[fecha_inicio]],2))&"-S"&TEXT(_xlfn.ISOWEEKNUM(tblOrdenes[[#This Row],[fecha_inicio]]),"00")) | Q7: =IF(tblOrdenes[[#This Row],[fecha_inicio]]="","",YEAR(tblOrdenes[[#This Row],[fecha_inicio]])) | R7: =IF(tblOrdenes[[#This Row],[fecha_inicio]]="","",MONTH(tblOrdenes[[#This Row],[fecha_inicio]])) | S7: =IF(tblOrdenes[[#This Row],[fecha_inicio]]="","",INDEX(lista_dias,WEEKDAY(tblOrdenes[[#This Row],[fecha_inicio]],2))) | T7: =IF(tblOrdenes[[#This Row],[tipo_ot]]="","",_xlfn.XLOOKUP(tblOrdenes[[#This Row],[tipo_ot]],tblTiposOT[codigo],tblTiposOT[clasificacion],"sin_clasificar")) | U7: =IF(tblOrdenes[[#This Row],[centro_costo]]="","",_xlfn.XLOOKUP(tblOrdenes[[#This Row],[centro_costo]],tblCECO[codigo],tblCECO[linea],"(sin catálogo)")) | V7: =IF(tblOrdenes[[#This Row],[centro_costo]]="","",_xlfn.XLOOKUP(tblOrdenes[[#This Row],[centro_costo]],tblCECO[codigo],tblCECO[area],"(sin catálogo)")) | W7: =IF(tblOrdenes[[#This Row],[centro_costo]]="","",_xlfn.XLOOKUP(tblOrdenes[[#This Row],[centro_costo]],tblCECO[codigo],tblCECO[coordinador],"(sin catálogo)")) | X7: =IF(tblOrdenes[[#This Row],[puesto_trabajo]]="","",_xlfn.XLOOKUP(tblOrdenes[[#This Row],[puesto_trabajo]],tblPuestos[codigo],tblPuestos[especialidad],"(sin catálogo)")) | Y7: =IF(tblOrdenes[[#This Row],[cod_actividad]]="","",_xlfn.XLOOKUP(tblOrdenes[[#This Row],[cod_actividad]],tblActividades[codigo],tblActividades[descripcion],"(sin catálogo)")) | Z7: =IF(tblOrdenes[[#This Row],[fecha_inicio]]="","",TODAY()-tblOrdenes[[#This Row],[fecha_inicio]]) | AA7: =IF(tblOrdenes[[#This Row],[backlog_dias]]="","",IF(tblOrdenes[[#This Row],[backlog_dias]]<0,"FUTURO",IF(tblOrdenes[[#This Row],[backlog_dias]]>p_dias_backlog_max,"BACKLOG","MES CORRIENTE"))) | AB7: =IF(tblOrdenes[[#This Row],[backlog_dias]]="",FALSE,AND(tblOrdenes[[#This Row],[backlog_dias]]>p_dias_backlog_min,tblOrdenes[[#This Row],[backlog_dias]]<=p_dias_backlog_max)) | AC7: Técnico 04 | AD7: =IF(tblOrdenes[[#This Row],[tecnico_asignado]]="","",_xlfn.XLOOKUP(tblOrdenes[[#This Row],[semana]]&"|"&tblOrdenes[[#This Row],[dia_semana]]&"|"&tblOrdenes[[#This Row],[tecnico_asignado]],tblAsignaciones[clave],tblAsignaciones[turno],"")) | AE7: =IF(tblOrdenes[[#This Row],[tecnico_asignado]]="","",SUMIFS(tblOrdenes[horas_efectivas],tblOrdenes[tecnico_asignado],tblOrdenes[[#This Row],[tecnico_asignado]],tblOrdenes[semana],tblOrdenes[[#This Row],[semana]],tblOrdenes[dia_semana],tblOrdenes[[#This Row],[dia_semana]])) | AF7: =IF(tblOrdenes[[#This Row],[HHA]]="","",p_factor_productividad*_xlfn.XLOOKUP(tblOrdenes[[#This Row],[semana]]&"|"&tblOrdenes[[#This Row],[dia_semana]]&"|"&tblOrdenes[[#This Row],[tecnico_asignado]],tblAsignaciones[clave],tblAsignaciones[horas_disponibles],0)-tblOrdenes[[#This Row],[HHA]]) | AG7: =IF(tblOrdenes[[#This Row],[orden]]="","",_xlfn.XLOOKUP(tblOrdenes[[#This Row],[id_operacion]],tblEjecucion[id_operacion],tblEjecucion[precio],0)) | AH7: =IF(tblOrdenes[[#This Row],[orden]]="","",MAX(0,_xlfn.XLOOKUP(tblOrdenes[[#This Row],[id_operacion]],tblEjecucion[id_operacion],tblEjecucion[costo_plan_total],0)-tblOrdenes[[#This Row],[costo_servicio]])) | AI7: =IF(tblOrdenes[[#This Row],[orden]]="","",tblOrdenes[[#This Row],[costo_servicio]]+tblOrdenes[[#This Row],[costo_materiales]]) | AL7: ACT-02.pdf | AM7: =IF(tblOrdenes[[#This Row],[link_checklist]]="","",HYPERLINK(p_ruta_base_checklists&tblOrdenes[[#This Row],[link_checklist]],"abrir")) | AO7: =IF(tblOrdenes[[#This Row],[orden]]="","",tblOrdenes[[#This Row],[orden]]&IF(tblOrdenes[[#This Row],[operacion]]="","0010",tblOrdenes[[#This Row],[operacion]]))
A8: OT-000005 | B8: 0010 | C8: Análisis predictivo — EQ-107 | D8: Análisis predictivo en EQ-107 | E8: EQ-107 | F8: CC-210 | G8: PU-MEC | H8: ACT-04 | I8: TIPO-P2 | J8: 46220 | K8: 8 | L8: 200 | N8: =IF(tblOrdenes[[#This Row],[orden]]="","",IF(tblOrdenes[[#This Row],[horas_ajustadas]]<>"",tblOrdenes[[#This Row],[horas_ajustadas]],IF(tblOrdenes[[#This Row],[horas_estimadas]]="","",tblOrdenes[[#This Row],[horas_estimadas]]))) | O8: =IF(tblOrdenes[[#This Row],[orden]]="","",_xlfn.XLOOKUP(_xlfn.XLOOKUP(tblOrdenes[[#This Row],[id_operacion]],tblEjecucion[id_operacion],tblEjecucion[estado_sistema],""),tblEstados[estado_sistema],tblEstados[estado_normalizado],"Pendiente")) | P8: =IF(tblOrdenes[[#This Row],[fecha_inicio]]="","",YEAR(tblOrdenes[[#This Row],[fecha_inicio]]+4-WEEKDAY(tblOrdenes[[#This Row],[fecha_inicio]],2))&"-S"&TEXT(_xlfn.ISOWEEKNUM(tblOrdenes[[#This Row],[fecha_inicio]]),"00")) | Q8: =IF(tblOrdenes[[#This Row],[fecha_inicio]]="","",YEAR(tblOrdenes[[#This Row],[fecha_inicio]])) | R8: =IF(tblOrdenes[[#This Row],[fecha_inicio]]="","",MONTH(tblOrdenes[[#This Row],[fecha_inicio]])) | S8: =IF(tblOrdenes[[#This Row],[fecha_inicio]]="","",INDEX(lista_dias,WEEKDAY(tblOrdenes[[#This Row],[fecha_inicio]],2))) | T8: =IF(tblOrdenes[[#This Row],[tipo_ot]]="","",_xlfn.XLOOKUP(tblOrdenes[[#This Row],[tipo_ot]],tblTiposOT[codigo],tblTiposOT[clasificacion],"sin_clasificar")) | U8: =IF(tblOrdenes[[#This Row],[centro_costo]]="","",_xlfn.XLOOKUP(tblOrdenes[[#This Row],[centro_costo]],tblCECO[codigo],tblCECO[linea],"(sin catálogo)")) | V8: =IF(tblOrdenes[[#This Row],[centro_costo]]="","",_xlfn.XLOOKUP(tblOrdenes[[#This Row],[centro_costo]],tblCECO[codigo],tblCECO[area],"(sin catálogo)")) | W8: =IF(tblOrdenes[[#This Row],[centro_costo]]="","",_xlfn.XLOOKUP(tblOrdenes[[#This Row],[centro_costo]],tblCECO[codigo],tblCECO[coordinador],"(sin catálogo)")) | X8: =IF(tblOrdenes[[#This Row],[puesto_trabajo]]="","",_xlfn.XLOOKUP(tblOrdenes[[#This Row],[puesto_trabajo]],tblPuestos[codigo],tblPuestos[especialidad],"(sin catálogo)")) | Y8: =IF(tblOrdenes[[#This Row],[cod_actividad]]="","",_xlfn.XLOOKUP(tblOrdenes[[#This Row],[cod_actividad]],tblActividades[codigo],tblActividades[descripcion],"(sin catálogo)")) | Z8: =IF(tblOrdenes[[#This Row],[fecha_inicio]]="","",TODAY()-tblOrdenes[[#This Row],[fecha_inicio]]) | AA8: =IF(tblOrdenes[[#This Row],[backlog_dias]]="","",IF(tblOrdenes[[#This Row],[backlog_dias]]<0,"FUTURO",IF(tblOrdenes[[#This Row],[backlog_dias]]>p_dias_backlog_max,"BACKLOG","MES CORRIENTE"))) | AB8: =IF(tblOrdenes[[#This Row],[backlog_dias]]="",FALSE,AND(tblOrdenes[[#This Row],[backlog_dias]]>p_dias_backlog_min,tblOrdenes[[#This Row],[backlog_dias]]<=p_dias_backlog_max)) | AC8: Técnico 01 | AD8: =IF(tblOrdenes[[#This Row],[tecnico_asignado]]="","",_xlfn.XLOOKUP(tblOrdenes[[#This Row],[semana]]&"|"&tblOrdenes[[#This Row],[dia_semana]]&"|"&tblOrdenes[[#This Row],[tecnico_asignado]],tblAsignaciones[clave],tblAsignaciones[turno],"")) | AE8: =IF(tblOrdenes[[#This Row],[tecnico_asignado]]="","",SUMIFS(tblOrdenes[horas_efectivas],tblOrdenes[tecnico_asignado],tblOrdenes[[#This Row],[tecnico_asignado]],tblOrdenes[semana],tblOrdenes[[#This Row],[semana]],tblOrdenes[dia_semana],tblOrdenes[[#This Row],[dia_semana]])) | AF8: =IF(tblOrdenes[[#This Row],[HHA]]="","",p_factor_productividad*_xlfn.XLOOKUP(tblOrdenes[[#This Row],[semana]]&"|"&tblOrdenes[[#This Row],[dia_semana]]&"|"&tblOrdenes[[#This Row],[tecnico_asignado]],tblAsignaciones[clave],tblAsignaciones[horas_disponibles],0)-tblOrdenes[[#This Row],[HHA]]) | AG8: =IF(tblOrdenes[[#This Row],[orden]]="","",_xlfn.XLOOKUP(tblOrdenes[[#This Row],[id_operacion]],tblEjecucion[id_operacion],tblEjecucion[precio],0)) | AH8: =IF(tblOrdenes[[#This Row],[orden]]="","",MAX(0,_xlfn.XLOOKUP(tblOrdenes[[#This Row],[id_operacion]],tblEjecucion[id_operacion],tblEjecucion[costo_plan_total],0)-tblOrdenes[[#This Row],[costo_servicio]])) | AI8: =IF(tblOrdenes[[#This Row],[orden]]="","",tblOrdenes[[#This Row],[costo_servicio]]+tblOrdenes[[#This Row],[costo_materiales]]) | AL8: ACT-04.pdf | AM8: =IF(tblOrdenes[[#This Row],[link_checklist]]="","",HYPERLINK(p_ruta_base_checklists&tblOrdenes[[#This Row],[link_checklist]],"abrir")) | AO8: =IF(tblOrdenes[[#This Row],[orden]]="","",tblOrdenes[[#This Row],[orden]]&IF(tblOrdenes[[#This Row],[operacion]]="","0010",tblOrdenes[[#This Row],[operacion]]))
A9: OT-000006 | B9: 0010 | C9: Inspección de rutina — EQ-110 | D9: Inspección de rutina en EQ-110 | E9: EQ-110 | F9: CC-310 | G9: PU-MEC | H9: ACT-01 | I9: TIPO-P1 | J9: 46216 | K9: 6 | L9: 150 | N9: =IF(tblOrdenes[[#This Row],[orden]]="","",IF(tblOrdenes[[#This Row],[horas_ajustadas]]<>"",tblOrdenes[[#This Row],[horas_ajustadas]],IF(tblOrdenes[[#This Row],[horas_estimadas]]="","",tblOrdenes[[#This Row],[horas_estimadas]]))) | O9: =IF(tblOrdenes[[#This Row],[orden]]="","",_xlfn.XLOOKUP(_xlfn.XLOOKUP(tblOrdenes[[#This Row],[id_operacion]],tblEjecucion[id_operacion],tblEjecucion[estado_sistema],""),tblEstados[estado_sistema],tblEstados[estado_normalizado],"Pendiente")) | P9: =IF(tblOrdenes[[#This Row],[fecha_inicio]]="","",YEAR(tblOrdenes[[#This Row],[fecha_inicio]]+4-WEEKDAY(tblOrdenes[[#This Row],[fecha_inicio]],2))&"-S"&TEXT(_xlfn.ISOWEEKNUM(tblOrdenes[[#This Row],[fecha_inicio]]),"00")) | Q9: =IF(tblOrdenes[[#This Row],[fecha_inicio]]="","",YEAR(tblOrdenes[[#This Row],[fecha_inicio]])) | R9: =IF(tblOrdenes[[#This Row],[fecha_inicio]]="","",MONTH(tblOrdenes[[#This Row],[fecha_inicio]])) | S9: =IF(tblOrdenes[[#This Row],[fecha_inicio]]="","",INDEX(lista_dias,WEEKDAY(tblOrdenes[[#This Row],[fecha_inicio]],2))) | T9: =IF(tblOrdenes[[#This Row],[tipo_ot]]="","",_xlfn.XLOOKUP(tblOrdenes[[#This Row],[tipo_ot]],tblTiposOT[codigo],tblTiposOT[clasificacion],"sin_clasificar")) | U9: =IF(tblOrdenes[[#This Row],[centro_costo]]="","",_xlfn.XLOOKUP(tblOrdenes[[#This Row],[centro_costo]],tblCECO[codigo],tblCECO[linea],"(sin catálogo)")) | V9: =IF(tblOrdenes[[#This Row],[centro_costo]]="","",_xlfn.XLOOKUP(tblOrdenes[[#This Row],[centro_costo]],tblCECO[codigo],tblCECO[area],"(sin catálogo)")) | W9: =IF(tblOrdenes[[#This Row],[centro_costo]]="","",_xlfn.XLOOKUP(tblOrdenes[[#This Row],[centro_costo]],tblCECO[codigo],tblCECO[coordinador],"(sin catálogo)")) | X9: =IF(tblOrdenes[[#This Row],[puesto_trabajo]]="","",_xlfn.XLOOKUP(tblOrdenes[[#This Row],[puesto_trabajo]],tblPuestos[codigo],tblPuestos[especialidad],"(sin catálogo)")) | Y9: =IF(tblOrdenes[[#This Row],[cod_actividad]]="","",_xlfn.XLOOKUP(tblOrdenes[[#This Row],[cod_actividad]],tblActividades[codigo],tblActividades[descripcion],"(sin catálogo)")) | Z9: =IF(tblOrdenes[[#This Row],[fecha_inicio]]="","",TODAY()-tblOrdenes[[#This Row],[fecha_inicio]]) | AA9: =IF(tblOrdenes[[#This Row],[backlog_dias]]="","",IF(tblOrdenes[[#This Row],[backlog_dias]]<0,"FUTURO",IF(tblOrdenes[[#This Row],[backlog_dias]]>p_dias_backlog_max,"BACKLOG","MES CORRIENTE"))) | AB9: =IF(tblOrdenes[[#This Row],[backlog_dias]]="",FALSE,AND(tblOrdenes[[#This Row],[backlog_dias]]>p_dias_backlog_min,tblOrdenes[[#This Row],[backlog_dias]]<=p_dias_backlog_max)) | AC9: Técnico 02 | AD9: =IF(tblOrdenes[[#This Row],[tecnico_asignado]]="","",_xlfn.XLOOKUP(tblOrdenes[[#This Row],[semana]]&"|"&tblOrdenes[[#This Row],[dia_semana]]&"|"&tblOrdenes[[#This Row],[tecnico_asignado]],tblAsignaciones[clave],tblAsignaciones[turno],"")) | AE9: =IF(tblOrdenes[[#This Row],[tecnico_asignado]]="","",SUMIFS(tblOrdenes[horas_efectivas],tblOrdenes[tecnico_asignado],tblOrdenes[[#This Row],[tecnico_asignado]],tblOrdenes[semana],tblOrdenes[[#This Row],[semana]],tblOrdenes[dia_semana],tblOrdenes[[#This Row],[dia_semana]])) | AF9: =IF(tblOrdenes[[#This Row],[HHA]]="","",p_factor_productividad*_xlfn.XLOOKUP(tblOrdenes[[#This Row],[semana]]&"|"&tblOrdenes[[#This Row],[dia_semana]]&"|"&tblOrdenes[[#This Row],[tecnico_asignado]],tblAsignaciones[clave],tblAsignaciones[horas_disponibles],0)-tblOrdenes[[#This Row],[HHA]]) | AG9: =IF(tblOrdenes[[#This Row],[orden]]="","",_xlfn.XLOOKUP(tblOrdenes[[#This Row],[id_operacion]],tblEjecucion[id_operacion],tblEjecucion[precio],0)) | AH9: =IF(tblOrdenes[[#This Row],[orden]]="","",MAX(0,_xlfn.XLOOKUP(tblOrdenes[[#This Row],[id_operacion]],tblEjecucion[id_operacion],tblEjecucion[costo_plan_total],0)-tblOrdenes[[#This Row],[costo_servicio]])) | AI9: =IF(tblOrdenes[[#This Row],[orden]]="","",tblOrdenes[[#This Row],[costo_servicio]]+tblOrdenes[[#This Row],[costo_materiales]]) | AL9: ACT-01.pdf | AM9: =IF(tblOrdenes[[#This Row],[link_checklist]]="","",HYPERLINK(p_ruta_base_checklists&tblOrdenes[[#This Row],[link_checklist]],"abrir")) | AO9: =IF(tblOrdenes[[#This Row],[orden]]="","",tblOrdenes[[#This Row],[orden]]&IF(tblOrdenes[[#This Row],[operacion]]="","0010",tblOrdenes[[#This Row],[operacion]]))
A10: OT-000007 | B10: 0010 | C10: Lubricación programada — EQ-103 | D10: Lubricación programada en EQ-103 | E10: EQ-103 | F10: CC-110 | G10: PU-MEC | H10: ACT-02 | I10: TIPO-P2 | J10: 46217 | K10: 10 | L10: 250 | N10: =IF(tblOrdenes[[#This Row],[orden]]="","",IF(tblOrdenes[[#This Row],[horas_ajustadas]]<>"",tblOrdenes[[#This Row],[horas_ajustadas]],IF(tblOrdenes[[#This Row],[horas_estimadas]]="","",tblOrdenes[[#This Row],[horas_estimadas]]))) | O10: =IF(tblOrdenes[[#This Row],[orden]]="","",_xlfn.XLOOKUP(_xlfn.XLOOKUP(tblOrdenes[[#This Row],[id_operacion]],tblEjecucion[id_operacion],tblEjecucion[estado_sistema],""),tblEstados[estado_sistema],tblEstados[estado_normalizado],"Pendiente")) | P10: =IF(tblOrdenes[[#This Row],[fecha_inicio]]="","",YEAR(tblOrdenes[[#This Row],[fecha_inicio]]+4-WEEKDAY(tblOrdenes[[#This Row],[fecha_inicio]],2))&"-S"&TEXT(_xlfn.ISOWEEKNUM(tblOrdenes[[#This Row],[fecha_inicio]]),"00")) | Q10: =IF(tblOrdenes[[#This Row],[fecha_inicio]]="","",YEAR(tblOrdenes[[#This Row],[fecha_inicio]])) | R10: =IF(tblOrdenes[[#This Row],[fecha_inicio]]="","",MONTH(tblOrdenes[[#This Row],[fecha_inicio]])) | S10: =IF(tblOrdenes[[#This Row],[fecha_inicio]]="","",INDEX(lista_dias,WEEKDAY(tblOrdenes[[#This Row],[fecha_inicio]],2))) | T10: =IF(tblOrdenes[[#This Row],[tipo_ot]]="","",_xlfn.XLOOKUP(tblOrdenes[[#This Row],[tipo_ot]],tblTiposOT[codigo],tblTiposOT[clasificacion],"sin_clasificar")) | U10: =IF(tblOrdenes[[#This Row],[centro_costo]]="","",_xlfn.XLOOKUP(tblOrdenes[[#This Row],[centro_costo]],tblCECO[codigo],tblCECO[linea],"(sin catálogo)")) | V10: =IF(tblOrdenes[[#This Row],[centro_costo]]="","",_xlfn.XLOOKUP(tblOrdenes[[#This Row],[centro_costo]],tblCECO[codigo],tblCECO[area],"(sin catálogo)")) | W10: =IF(tblOrdenes[[#This Row],[centro_costo]]="","",_xlfn.XLOOKUP(tblOrdenes[[#This Row],[centro_costo]],tblCECO[codigo],tblCECO[coordinador],"(sin catálogo)")) | X10: =IF(tblOrdenes[[#This Row],[puesto_trabajo]]="","",_xlfn.XLOOKUP(tblOrdenes[[#This Row],[puesto_trabajo]],tblPuestos[codigo],tblPuestos[especialidad],"(sin catálogo)")) | Y10: =IF(tblOrdenes[[#This Row],[cod_actividad]]="","",_xlfn.XLOOKUP(tblOrdenes[[#This Row],[cod_actividad]],tblActividades[codigo],tblActividades[descripcion],"(sin catálogo)")) | Z10: =IF(tblOrdenes[[#This Row],[fecha_inicio]]="","",TODAY()-tblOrdenes[[#This Row],[fecha_inicio]]) | AA10: =IF(tblOrdenes[[#This Row],[backlog_dias]]="","",IF(tblOrdenes[[#This Row],[backlog_dias]]<0,"FUTURO",IF(tblOrdenes[[#This Row],[backlog_dias]]>p_dias_backlog_max,"BACKLOG","MES CORRIENTE"))) | AB10: =IF(tblOrdenes[[#This Row],[backlog_dias]]="",FALSE,AND(tblOrdenes[[#This Row],[backlog_dias]]>p_dias_backlog_min,tblOrdenes[[#This Row],[backlog_dias]]<=p_dias_backlog_max)) | AC10: Técnico 03 | AD10: =IF(tblOrdenes[[#This Row],[tecnico_asignado]]="","",_xlfn.XLOOKUP(tblOrdenes[[#This Row],[semana]]&"|"&tblOrdenes[[#This Row],[dia_semana]]&"|"&tblOrdenes[[#This Row],[tecnico_asignado]],tblAsignaciones[clave],tblAsignaciones[turno],"")) | AE10: =IF(tblOrdenes[[#This Row],[tecnico_asignado]]="","",SUMIFS(tblOrdenes[horas_efectivas],tblOrdenes[tecnico_asignado],tblOrdenes[[#This Row],[tecnico_asignado]],tblOrdenes[semana],tblOrdenes[[#This Row],[semana]],tblOrdenes[dia_semana],tblOrdenes[[#This Row],[dia_semana]])) | AF10: =IF(tblOrdenes[[#This Row],[HHA]]="","",p_factor_productividad*_xlfn.XLOOKUP(tblOrdenes[[#This Row],[semana]]&"|"&tblOrdenes[[#This Row],[dia_semana]]&"|"&tblOrdenes[[#This Row],[tecnico_asignado]],tblAsignaciones[clave],tblAsignaciones[horas_disponibles],0)-tblOrdenes[[#This Row],[HHA]]) | AG10: =IF(tblOrdenes[[#This Row],[orden]]="","",_xlfn.XLOOKUP(tblOrdenes[[#This Row],[id_operacion]],tblEjecucion[id_operacion],tblEjecucion[precio],0)) | AH10: =IF(tblOrdenes[[#This Row],[orden]]="","",MAX(0,_xlfn.XLOOKUP(tblOrdenes[[#This Row],[id_operacion]],tblEjecucion[id_operacion],tblEjecucion[costo_plan_total],0)-tblOrdenes[[#This Row],[costo_servicio]])) | AI10: =IF(tblOrdenes[[#This Row],[orden]]="","",tblOrdenes[[#This Row],[costo_servicio]]+tblOrdenes[[#This Row],[costo_materiales]]) | AL10: ACT-02.pdf | AM10: =IF(tblOrdenes[[#This Row],[link_checklist]]="","",HYPERLINK(p_ruta_base_checklists&tblOrdenes[[#This Row],[link_checklist]],"abrir")) | AO10: =IF(tblOrdenes[[#This Row],[orden]]="","",tblOrdenes[[#This Row],[orden]]&IF(tblOrdenes[[#This Row],[operacion]]="","0010",tblOrdenes[[#This Row],[operacion]]))
A11: OT-000008 | B11: 0010 | C11: Análisis predictivo — EQ-106 | D11: Análisis predictivo en EQ-106 | E11: EQ-106 | F11: CC-210 | G11: PU-MEC | H11: ACT-04 | I11: TIPO-P1 | J11: 46218 | K11: 8 | L11: 200 | N11: =IF(tblOrdenes[[#This Row],[orden]]="","",IF(tblOrdenes[[#This Row],[horas_ajustadas]]<>"",tblOrdenes[[#This Row],[horas_ajustadas]],IF(tblOrdenes[[#This Row],[horas_estimadas]]="","",tblOrdenes[[#This Row],[horas_estimadas]]))) | O11: =IF(tblOrdenes[[#This Row],[orden]]="","",_xlfn.XLOOKUP(_xlfn.XLOOKUP(tblOrdenes[[#This Row],[id_operacion]],tblEjecucion[id_operacion],tblEjecucion[estado_sistema],""),tblEstados[estado_sistema],tblEstados[estado_normalizado],"Pendiente")) | P11: =IF(tblOrdenes[[#This Row],[fecha_inicio]]="","",YEAR(tblOrdenes[[#This Row],[fecha_inicio]]+4-WEEKDAY(tblOrdenes[[#This Row],[fecha_inicio]],2))&"-S"&TEXT(_xlfn.ISOWEEKNUM(tblOrdenes[[#This Row],[fecha_inicio]]),"00")) | Q11: =IF(tblOrdenes[[#This Row],[fecha_inicio]]="","",YEAR(tblOrdenes[[#This Row],[fecha_inicio]])) | R11: =IF(tblOrdenes[[#This Row],[fecha_inicio]]="","",MONTH(tblOrdenes[[#This Row],[fecha_inicio]])) | S11: =IF(tblOrdenes[[#This Row],[fecha_inicio]]="","",INDEX(lista_dias,WEEKDAY(tblOrdenes[[#This Row],[fecha_inicio]],2))) | T11: =IF(tblOrdenes[[#This Row],[tipo_ot]]="","",_xlfn.XLOOKUP(tblOrdenes[[#This Row],[tipo_ot]],tblTiposOT[codigo],tblTiposOT[clasificacion],"sin_clasificar")) | U11: =IF(tblOrdenes[[#This Row],[centro_costo]]="","",_xlfn.XLOOKUP(tblOrdenes[[#This Row],[centro_costo]],tblCECO[codigo],tblCECO[linea],"(sin catálogo)")) | V11: =IF(tblOrdenes[[#This Row],[centro_costo]]="","",_xlfn.XLOOKUP(tblOrdenes[[#This Row],[centro_costo]],tblCECO[codigo],tblCECO[area],"(sin catálogo)")) | W11: =IF(tblOrdenes[[#This Row],[centro_costo]]="","",_xlfn.XLOOKUP(tblOrdenes[[#This Row],[centro_costo]],tblCECO[codigo],tblCECO[coordinador],"(sin catálogo)")) | X11: =IF(tblOrdenes[[#This Row],[puesto_trabajo]]="","",_xlfn.XLOOKUP(tblOrdenes[[#This Row],[puesto_trabajo]],tblPuestos[codigo],tblPuestos[especialidad],"(sin catálogo)")) | Y11: =IF(tblOrdenes[[#This Row],[cod_actividad]]="","",_xlfn.XLOOKUP(tblOrdenes[[#This Row],[cod_actividad]],tblActividades[codigo],tblActividades[descripcion],"(sin catálogo)")) | Z11: =IF(tblOrdenes[[#This Row],[fecha_inicio]]="","",TODAY()-tblOrdenes[[#This Row],[fecha_inicio]]) | AA11: =IF(tblOrdenes[[#This Row],[backlog_dias]]="","",IF(tblOrdenes[[#This Row],[backlog_dias]]<0,"FUTURO",IF(tblOrdenes[[#This Row],[backlog_dias]]>p_dias_backlog_max,"BACKLOG","MES CORRIENTE"))) | AB11: =IF(tblOrdenes[[#This Row],[backlog_dias]]="",FALSE,AND(tblOrdenes[[#This Row],[backlog_dias]]>p_dias_backlog_min,tblOrdenes[[#This Row],[backlog_dias]]<=p_dias_backlog_max)) | AC11: Técnico 04 | AD11: =IF(tblOrdenes[[#This Row],[tecnico_asignado]]="","",_xlfn.XLOOKUP(tblOrdenes[[#This Row],[semana]]&"|"&tblOrdenes[[#This Row],[dia_semana]]&"|"&tblOrdenes[[#This Row],[tecnico_asignado]],tblAsignaciones[clave],tblAsignaciones[turno],"")) | AE11: =IF(tblOrdenes[[#This Row],[tecnico_asignado]]="","",SUMIFS(tblOrdenes[horas_efectivas],tblOrdenes[tecnico_asignado],tblOrdenes[[#This Row],[tecnico_asignado]],tblOrdenes[semana],tblOrdenes[[#This Row],[semana]],tblOrdenes[dia_semana],tblOrdenes[[#This Row],[dia_semana]])) | AF11: =IF(tblOrdenes[[#This Row],[HHA]]="","",p_factor_productividad*_xlfn.XLOOKUP(tblOrdenes[[#This Row],[semana]]&"|"&tblOrdenes[[#This Row],[dia_semana]]&"|"&tblOrdenes[[#This Row],[tecnico_asignado]],tblAsignaciones[clave],tblAsignaciones[horas_disponibles],0)-tblOrdenes[[#This Row],[HHA]]) | AG11: =IF(tblOrdenes[[#This Row],[orden]]="","",_xlfn.XLOOKUP(tblOrdenes[[#This Row],[id_operacion]],tblEjecucion[id_operacion],tblEjecucion[precio],0)) | AH11: =IF(tblOrdenes[[#This Row],[orden]]="","",MAX(0,_xlfn.XLOOKUP(tblOrdenes[[#This Row],[id_operacion]],tblEjecucion[id_operacion],tblEjecucion[costo_plan_total],0)-tblOrdenes[[#This Row],[costo_servicio]])) | AI11: =IF(tblOrdenes[[#This Row],[orden]]="","",tblOrdenes[[#This Row],[costo_servicio]]+tblOrdenes[[#This Row],[costo_materiales]]) | AL11: ACT-04.pdf | AM11: =IF(tblOrdenes[[#This Row],[link_checklist]]="","",HYPERLINK(p_ruta_base_checklists&tblOrdenes[[#This Row],[link_checklist]],"abrir")) | AO11: =IF(tblOrdenes[[#This Row],[orden]]="","",tblOrdenes[[#This Row],[orden]]&IF(tblOrdenes[[#This Row],[operacion]]="","0010",tblOrdenes[[#This Row],[operacion]]))
A12: OT-000009 | B12: 0010 | C12: Inspección de rutina — EQ-110 | D12: Inspección de rutina en EQ-110 | E12: EQ-110 | F12: CC-310 | G12: PU-MEC | H12: ACT-01 | I12: TIPO-P2 | J12: 46219 | K12: 6 | L12: 150 | N12: =IF(tblOrdenes[[#This Row],[orden]]="","",IF(tblOrdenes[[#This Row],[horas_ajustadas]]<>"",tblOrdenes[[#This Row],[horas_ajustadas]],IF(tblOrdenes[[#This Row],[horas_estimadas]]="","",tblOrdenes[[#This Row],[horas_estimadas]]))) | O12: =IF(tblOrdenes[[#This Row],[orden]]="","",_xlfn.XLOOKUP(_xlfn.XLOOKUP(tblOrdenes[[#This Row],[id_operacion]],tblEjecucion[id_operacion],tblEjecucion[estado_sistema],""),tblEstados[estado_sistema],tblEstados[estado_normalizado],"Pendiente")) | P12: =IF(tblOrdenes[[#This Row],[fecha_inicio]]="","",YEAR(tblOrdenes[[#This Row],[fecha_inicio]]+4-WEEKDAY(tblOrdenes[[#This Row],[fecha_inicio]],2))&"-S"&TEXT(_xlfn.ISOWEEKNUM(tblOrdenes[[#This Row],[fecha_inicio]]),"00")) | Q12: =IF(tblOrdenes[[#This Row],[fecha_inicio]]="","",YEAR(tblOrdenes[[#This Row],[fecha_inicio]])) | R12: =IF(tblOrdenes[[#This Row],[fecha_inicio]]="","",MONTH(tblOrdenes[[#This Row],[fecha_inicio]])) | S12: =IF(tblOrdenes[[#This Row],[fecha_inicio]]="","",INDEX(lista_dias,WEEKDAY(tblOrdenes[[#This Row],[fecha_inicio]],2))) | T12: =IF(tblOrdenes[[#This Row],[tipo_ot]]="","",_xlfn.XLOOKUP(tblOrdenes[[#This Row],[tipo_ot]],tblTiposOT[codigo],tblTiposOT[clasificacion],"sin_clasificar")) | U12: =IF(tblOrdenes[[#This Row],[centro_costo]]="","",_xlfn.XLOOKUP(tblOrdenes[[#This Row],[centro_costo]],tblCECO[codigo],tblCECO[linea],"(sin catálogo)")) | V12: =IF(tblOrdenes[[#This Row],[centro_costo]]="","",_xlfn.XLOOKUP(tblOrdenes[[#This Row],[centro_costo]],tblCECO[codigo],tblCECO[area],"(sin catálogo)")) | W12: =IF(tblOrdenes[[#This Row],[centro_costo]]="","",_xlfn.XLOOKUP(tblOrdenes[[#This Row],[centro_costo]],tblCECO[codigo],tblCECO[coordinador],"(sin catálogo)")) | X12: =IF(tblOrdenes[[#This Row],[puesto_trabajo]]="","",_xlfn.XLOOKUP(tblOrdenes[[#This Row],[puesto_trabajo]],tblPuestos[codigo],tblPuestos[especialidad],"(sin catálogo)")) | Y12: =IF(tblOrdenes[[#This Row],[cod_actividad]]="","",_xlfn.XLOOKUP(tblOrdenes[[#This Row],[cod_actividad]],tblActividades[codigo],tblActividades[descripcion],"(sin catálogo)")) | Z12: =IF(tblOrdenes[[#This Row],[fecha_inicio]]="","",TODAY()-tblOrdenes[[#This Row],[fecha_inicio]]) | AA12: =IF(tblOrdenes[[#This Row],[backlog_dias]]="","",IF(tblOrdenes[[#This Row],[backlog_dias]]<0,"FUTURO",IF(tblOrdenes[[#This Row],[backlog_dias]]>p_dias_backlog_max,"BACKLOG","MES CORRIENTE"))) | AB12: =IF(tblOrdenes[[#This Row],[backlog_dias]]="",FALSE,AND(tblOrdenes[[#This Row],[backlog_dias]]>p_dias_backlog_min,tblOrdenes[[#This Row],[backlog_dias]]<=p_dias_backlog_max)) | AC12: Técnico 01 | AD12: =IF(tblOrdenes[[#This Row],[tecnico_asignado]]="","",_xlfn.XLOOKUP(tblOrdenes[[#This Row],[semana]]&"|"&tblOrdenes[[#This Row],[dia_semana]]&"|"&tblOrdenes[[#This Row],[tecnico_asignado]],tblAsignaciones[clave],tblAsignaciones[turno],"")) | AE12: =IF(tblOrdenes[[#This Row],[tecnico_asignado]]="","",SUMIFS(tblOrdenes[horas_efectivas],tblOrdenes[tecnico_asignado],tblOrdenes[[#This Row],[tecnico_asignado]],tblOrdenes[semana],tblOrdenes[[#This Row],[semana]],tblOrdenes[dia_semana],tblOrdenes[[#This Row],[dia_semana]])) | AF12: =IF(tblOrdenes[[#This Row],[HHA]]="","",p_factor_productividad*_xlfn.XLOOKUP(tblOrdenes[[#This Row],[semana]]&"|"&tblOrdenes[[#This Row],[dia_semana]]&"|"&tblOrdenes[[#This Row],[tecnico_asignado]],tblAsignaciones[clave],tblAsignaciones[horas_disponibles],0)-tblOrdenes[[#This Row],[HHA]]) | AG12: =IF(tblOrdenes[[#This Row],[orden]]="","",_xlfn.XLOOKUP(tblOrdenes[[#This Row],[id_operacion]],tblEjecucion[id_operacion],tblEjecucion[precio],0)) | AH12: =IF(tblOrdenes[[#This Row],[orden]]="","",MAX(0,_xlfn.XLOOKUP(tblOrdenes[[#This Row],[id_operacion]],tblEjecucion[id_operacion],tblEjecucion[costo_plan_total],0)-tblOrdenes[[#This Row],[costo_servicio]])) | AI12: =IF(tblOrdenes[[#This Row],[orden]]="","",tblOrdenes[[#This Row],[costo_servicio]]+tblOrdenes[[#This Row],[costo_materiales]]) | AL12: ACT-01.pdf | AM12: =IF(tblOrdenes[[#This Row],[link_checklist]]="","",HYPERLINK(p_ruta_base_checklists&tblOrdenes[[#This Row],[link_checklist]],"abrir")) | AO12: =IF(tblOrdenes[[#This Row],[orden]]="","",tblOrdenes[[#This Row],[orden]]&IF(tblOrdenes[[#This Row],[operacion]]="","0010",tblOrdenes[[#This Row],[operacion]]))
A13: OT-000010 | B13: 0010 | C13: Lubricación programada — EQ-101 | D13: Lubricación programada en EQ-101 | E13: EQ-101 | F13: CC-110 | G13: PU-MEC | H13: ACT-02 | I13: TIPO-P1 | J13: 46220 | K13: 8 | L13: 200 | N13: =IF(tblOrdenes[[#This Row],[orden]]="","",IF(tblOrdenes[[#This Row],[horas_ajustadas]]<>"",tblOrdenes[[#This Row],[horas_ajustadas]],IF(tblOrdenes[[#This Row],[horas_estimadas]]="","",tblOrdenes[[#This Row],[horas_estimadas]]))) | O13: =IF(tblOrdenes[[#This Row],[orden]]="","",_xlfn.XLOOKUP(_xlfn.XLOOKUP(tblOrdenes[[#This Row],[id_operacion]],tblEjecucion[id_operacion],tblEjecucion[estado_sistema],""),tblEstados[estado_sistema],tblEstados[estado_normalizado],"Pendiente")) | P13: =IF(tblOrdenes[[#This Row],[fecha_inicio]]="","",YEAR(tblOrdenes[[#This Row],[fecha_inicio]]+4-WEEKDAY(tblOrdenes[[#This Row],[fecha_inicio]],2))&"-S"&TEXT(_xlfn.ISOWEEKNUM(tblOrdenes[[#This Row],[fecha_inicio]]),"00")) | Q13: =IF(tblOrdenes[[#This Row],[fecha_inicio]]="","",YEAR(tblOrdenes[[#This Row],[fecha_inicio]])) | R13: =IF(tblOrdenes[[#This Row],[fecha_inicio]]="","",MONTH(tblOrdenes[[#This Row],[fecha_inicio]])) | S13: =IF(tblOrdenes[[#This Row],[fecha_inicio]]="","",INDEX(lista_dias,WEEKDAY(tblOrdenes[[#This Row],[fecha_inicio]],2))) | T13: =IF(tblOrdenes[[#This Row],[tipo_ot]]="","",_xlfn.XLOOKUP(tblOrdenes[[#This Row],[tipo_ot]],tblTiposOT[codigo],tblTiposOT[clasificacion],"sin_clasificar")) | U13: =IF(tblOrdenes[[#This Row],[centro_costo]]="","",_xlfn.XLOOKUP(tblOrdenes[[#This Row],[centro_costo]],tblCECO[codigo],tblCECO[linea],"(sin catálogo)")) | V13: =IF(tblOrdenes[[#This Row],[centro_costo]]="","",_xlfn.XLOOKUP(tblOrdenes[[#This Row],[centro_costo]],tblCECO[codigo],tblCECO[area],"(sin catálogo)")) | W13: =IF(tblOrdenes[[#This Row],[centro_costo]]="","",_xlfn.XLOOKUP(tblOrdenes[[#This Row],[centro_costo]],tblCECO[codigo],tblCECO[coordinador],"(sin catálogo)")) | X13: =IF(tblOrdenes[[#This Row],[puesto_trabajo]]="","",_xlfn.XLOOKUP(tblOrdenes[[#This Row],[puesto_trabajo]],tblPuestos[codigo],tblPuestos[especialidad],"(sin catálogo)")) | Y13: =IF(tblOrdenes[[#This Row],[cod_actividad]]="","",_xlfn.XLOOKUP(tblOrdenes[[#This Row],[cod_actividad]],tblActividades[codigo],tblActividades[descripcion],"(sin catálogo)")) | Z13: =IF(tblOrdenes[[#This Row],[fecha_inicio]]="","",TODAY()-tblOrdenes[[#This Row],[fecha_inicio]]) | AA13: =IF(tblOrdenes[[#This Row],[backlog_dias]]="","",IF(tblOrdenes[[#This Row],[backlog_dias]]<0,"FUTURO",IF(tblOrdenes[[#This Row],[backlog_dias]]>p_dias_backlog_max,"BACKLOG","MES CORRIENTE"))) | AB13: =IF(tblOrdenes[[#This Row],[backlog_dias]]="",FALSE,AND(tblOrdenes[[#This Row],[backlog_dias]]>p_dias_backlog_min,tblOrdenes[[#This Row],[backlog_dias]]<=p_dias_backlog_max)) | AC13: Técnico 02 | AD13: =IF(tblOrdenes[[#This Row],[tecnico_asignado]]="","",_xlfn.XLOOKUP(tblOrdenes[[#This Row],[semana]]&"|"&tblOrdenes[[#This Row],[dia_semana]]&"|"&tblOrdenes[[#This Row],[tecnico_asignado]],tblAsignaciones[clave],tblAsignaciones[turno],"")) | AE13: =IF(tblOrdenes[[#This Row],[tecnico_asignado]]="","",SUMIFS(tblOrdenes[horas_efectivas],tblOrdenes[tecnico_asignado],tblOrdenes[[#This Row],[tecnico_asignado]],tblOrdenes[semana],tblOrdenes[[#This Row],[semana]],tblOrdenes[dia_semana],tblOrdenes[[#This Row],[dia_semana]])) | AF13: =IF(tblOrdenes[[#This Row],[HHA]]="","",p_factor_productividad*_xlfn.XLOOKUP(tblOrdenes[[#This Row],[semana]]&"|"&tblOrdenes[[#This Row],[dia_semana]]&"|"&tblOrdenes[[#This Row],[tecnico_asignado]],tblAsignaciones[clave],tblAsignaciones[horas_disponibles],0)-tblOrdenes[[#This Row],[HHA]]) | AG13: =IF(tblOrdenes[[#This Row],[orden]]="","",_xlfn.XLOOKUP(tblOrdenes[[#This Row],[id_operacion]],tblEjecucion[id_operacion],tblEjecucion[precio],0)) | AH13: =IF(tblOrdenes[[#This Row],[orden]]="","",MAX(0,_xlfn.XLOOKUP(tblOrdenes[[#This Row],[id_operacion]],tblEjecucion[id_operacion],tblEjecucion[costo_plan_total],0)-tblOrdenes[[#This Row],[costo_servicio]])) | AI13: =IF(tblOrdenes[[#This Row],[orden]]="","",tblOrdenes[[#This Row],[costo_servicio]]+tblOrdenes[[#This Row],[costo_materiales]]) | AL13: ACT-02.pdf | AM13: =IF(tblOrdenes[[#This Row],[link_checklist]]="","",HYPERLINK(p_ruta_base_checklists&tblOrdenes[[#This Row],[link_checklist]],"abrir")) | AO13: =IF(tblOrdenes[[#This Row],[orden]]="","",tblOrdenes[[#This Row],[orden]]&IF(tblOrdenes[[#This Row],[operacion]]="","0010",tblOrdenes[[#This Row],[operacion]]))
