Workbook
Name p_moneda: PARAMETROS!$B$6
Name p_horas_jornada: PARAMETROS!$B$7
Name p_factor_productividad: PARAMETROS!$B$8
Name p_dias_backlog_max: PARAMETROS!$B$11
Name p_dias_backlog_min: PARAMETROS!$B$12
Name p_meta_adherencia: PARAMETROS!$B$13
Name p_meta_ratio_prev_corr: PARAMETROS!$B$14
Name p_ruta_base_checklists: PARAMETROS!$B$16
Name p_top_tareas: PARAMETROS!$B$17
Name p_nombre_empresa: PARAMETROS!$B$4
Name p_nombre_planta: PARAMETROS!$B$5
Name p_dias_laborables_base: PARAMETROS!$B$18
Name p_base_semanal_horas: PARAMETROS!$B$19
Name p_semana_referencia: PARAMETROS!$B$20
Name p_tolerancia_horas_bono: PARAMETROS!$B$21
Name p_anio_presupuesto: PARAMETROS!$B$22
Name p_tolerancia_desviacion_presupuesto: PARAMETROS!$B$23
Name p_fecha_datos: PARAMETROS!$B$24
Name p_meta_pct_predictivo: PARAMETROS!$B$25
Name p_meta_pct_preventivo: PARAMETROS!$B$26
Name p_meta_pct_correctivo_programado: PARAMETROS!$B$27
Name p_meta_pct_emergencia: PARAMETROS!$B$28
Name lista_no_disponible: PARAMETROS!$G$5:$G$6
Name lista_dias: PARAMETROS!$I$5:$I$11
Name lista_tecnicos: TECNICOS!$K$4:$K$19
Name patronHabil: CALENDARIO!$B$5:$B$11
Name cal_fechas: CALENDARIO!$I$5:$I$764
Name cal_habil: CALENDARIO!$J$5:$J$764
Name lista_semanas_plan: PLAN_SEMANAL!$X$3:$X$60
Name lista_turnos: CAT_TURNOS!$G$4:$G$9
Name lista_f_turno: =PARAMETROS!$K$5:INDEX(PARAMETROS!$K$5:$K$24,MAX(1,COUNTIF(PARAMETROS!$K$5:$K$24,"?*")))
Name lista_f_area: =PARAMETROS!$L$5:INDEX(PARAMETROS!$L$5:$L$30,MAX(1,COUNTIF(PARAMETROS!$L$5:$L$30,"?*")))
Name lista_areas: =PARAMETROS!$M$5:INDEX(PARAMETROS!$M$5:$M$29,MAX(1,COUNTIF(PARAMETROS!$M$5:$M$29,"?*")))
Name lista_f_coordinador: =PARAMETROS!$N$5:INDEX(PARAMETROS!$N$5:$N$30,MAX(1,COUNTIF(PARAMETROS!$N$5:$N$30,"?*")))
Name lista_f_subarea: =PARAMETROS!$O$5:INDEX(PARAMETROS!$O$5:$O$30,MAX(1,COUNTIF(PARAMETROS!$O$5:$O$30,"?*")))
Name lista_subareas: =PARAMETROS!$P$5:INDEX(PARAMETROS!$P$5:$P$29,MAX(1,COUNTIF(PARAMETROS!$P$5:$P$29,"?*")))
Name lista_f_especialidad: =PARAMETROS!$Q$5:INDEX(PARAMETROS!$Q$5:$Q$25,MAX(1,COUNTIF(PARAMETROS!$Q$5:$Q$25,"?*")))
Name lista_esp_propias: =PARAMETROS!$R$5:INDEX(PARAMETROS!$R$5:$R$24,MAX(1,COUNTIF(PARAMETROS!$R$5:$R$24,"?*")))
Name lista_ceco: =PARAMETROS!$S$5:INDEX(PARAMETROS!$S$5:$S$29,MAX(1,COUNTIF(PARAMETROS!$S$5:$S$29,"?*")))
Name lista_puestos: =PARAMETROS!$T$5:INDEX(PARAMETROS!$T$5:$T$24,MAX(1,COUNTIF(PARAMETROS!$T$5:$T$24,"?*")))
Name lista_actividades: =PARAMETROS!$U$5:INDEX(PARAMETROS!$U$5:$U$27,MAX(1,COUNTIF(PARAMETROS!$U$5:$U$27,"?*")))
Name lista_tipos_ot: =PARAMETROS!$V$5:INDEX(PARAMETROS!$V$5:$V$24,MAX(1,COUNTIF(PARAMETROS!$V$5:$V$24,"?*")))
Name lista_supervisores: =PARAMETROS!$W$5:INDEX(PARAMETROS!$W$5:$W$22,MAX(1,COUNTIF(PARAMETROS!$W$5:$W$22,"?*")))
Name lista_motivos_ausencia: =PARAMETROS!$X$5:INDEX(PARAMETROS!$X$5:$X$22,MAX(1,COUNTIF(PARAMETROS!$X$5:$X$22,"?*")))
Name lista_meses_dash: DASHBOARD!$X$3:$X$20

Sheet DASHBOARD
A1: ="TABLERO DE MANTENIMIENTO — "&p_nombre_planta&" · "&p_nombre_empresa
A2: Solo lectura: cada indicador se lee de su hoja de origen (botonera de abajo). El selector ofrece el calendario completo, no solo los meses con datos: un mes sin datos sale en BLANCO (blanco = no hay dato; cero = hubo trabajo y no se cumplió). Las metas de mix son convención de industria, NO una norma; se ajustan en PARAMETROS. | X2: meses con datos (validación) — no editar
A3: Mes: | B3: 2026-07 | D3: ="Fecha de datos: "&TEXT(p_fecha_datos,"yyyy-mm-dd")&" · "&IF($B$3=YEAR(p_fecha_datos)&"-"&TEXT(MONTH(p_fecha_datos),"00"),"MES EN CURSO: incluye hasta el "&TEXT(p_fecha_datos-1,"yyyy-mm-dd")&" (ni el día de la fecha de datos ni los posteriores entran)",IF($B$3<YEAR(p_fecha_datos)&"-"&TEXT(MONTH(p_fecha_datos),"00"),"mes cerrado: incluye el mes completo","mes futuro: muestra lo PLANIFICADO del mes completo")) | X3: 2025-10
A4: =HYPERLINK("#PLAN_SEMANAL!A1","▸ PLAN SEMANAL") | C4: =HYPERLINK("#ADHERENCIA!A1","▸ ADHERENCIA") | E4: =HYPERLINK("#PERFIL_HH!A1","▸ PERFIL HH") | G4: =HYPERLINK("#BACKLOG!A1","▸ BACKLOG") | I4: =HYPERLINK("#PRESUPUESTO!A1","▸ PRESUPUESTO") | K4: =HYPERLINK("#ORDENES!A1","▸ ORDENES") | M4: =HYPERLINK("#VALIDACION!A1","▸ VALIDACION") | X4: 2025-11
X5: 2025-12
A6: 1 · ADHERENCIA AL PROGRAMA | G6: 2 · % CARGA DE CAPACIDAD | M6: 3 · SEMANAS DE BACKLOG | X6: 2026-01
A7: =IFERROR(INDEX(ADHERENCIA!$E$134:$E$151,MATCH($B$3,ADHERENCIA!$A$134:$A$151,0)),"") | G7: =IFERROR(INDEX(PERFIL_HH!$L$373:$L$390,MATCH($B$3,PERFIL_HH!$A$373:$A$390,0)),"") | M7: =IFERROR(INDEX(BACKLOG!$F$34:$F$51,MATCH($B$3,BACKLOG!$A$34:$A$51,0)),"") | X7: 2026-02
X8: 2026-03
A9: ="meta "&TEXT(p_meta_adherencia,"0%")&" · REGLA-7, solo días hábiles" | G9: ="capacidad PRODUCTIVA = disponible × "&TEXT(p_factor_productividad,"0%")&" · no es el 100 % del tiempo de presencia" | M9: HH pendientes al corte ÷ capacidad productiva de una semana | X9: 2026-04
A10: origen: ADHERENCIA › MES A MES | G10: origen: PERFIL_HH › MES A MES | M10: origen: BACKLOG › AL CORTE (el detalle por tramos, en la hoja) | X10: 2026-05
X11: 2026-06
A12: 4 · EJECUCIÓN OPEX (acumulada) | G12: 5 · CUMPLIMIENTO DE LUBRICACIÓN | M12: 6 · CUMPLIMIENTO DE CALIBRACIONES | X12: 2026-07
A13: =IF(VALUE(LEFT($B$3,4))<>p_anio_presupuesto,"",IF(SUMPRODUCT(({1,2,3,4,5,6,7,8,9,10,11,12}<=VALUE(RIGHT($B$3,2)))*(PRESUPUESTO!$C$30:$N$30))=0,"",SUMPRODUCT(({1,2,3,4,5,6,7,8,9,10,11,12}<=VALUE(RIGHT($B$3,2)))*(PRESUPUESTO!$C$43:$N$43))/SUMPRODUCT(({1,2,3,4,5,6,7,8,9,10,11,12}<=VALUE(RIGHT($B$3,2)))*(PRESUPUESTO!$C$30:$N$30)))) | G13: =IFERROR(INDEX(ADHERENCIA!$M$134:$M$151,MATCH($B$3,ADHERENCIA!$A$134:$A$151,0)),"") | M13: =IFERROR(INDEX(ADHERENCIA!$I$134:$I$151,MATCH($B$3,ADHERENCIA!$A$134:$A$151,0)),"") | X13: 2026-08
X14: 2026-09
A15: ="real ÷ presupuesto, enero → mes elegido · tolerancia "&TEXT(p_tolerancia_desviacion_presupuesto,"0%") | G15: ="lubricacion cerradas ÷ programadas del mes · vencidas: "&$G$17 | M15: ="calibracion cerradas ÷ programadas del mes · vencidas: "&$M$17 | X15: 2026-10
A16: origen: PRESUPUESTO › filas TOTAL GENERAL | G16: origen: ADHERENCIA › MES A MES (rubro lubricacion) | M16: origen: ADHERENCIA › MES A MES (rubro calibracion) | X16: 2026-11
G17: =IFERROR(INDEX(ADHERENCIA!$N$134:$N$151,MATCH($B$3,ADHERENCIA!$A$134:$A$151,0)),"") | H17: ← lubricacion vencidas al corte (celda de apoyo del semáforo) | M17: =IFERROR(INDEX(ADHERENCIA!$J$134:$J$151,MATCH($B$3,ADHERENCIA!$A$134:$A$151,0)),"") | N17: ← calibracion vencidas al corte (celda de apoyo del semáforo) | X17: 2026-12
X18: 2027-01
X19: 2027-02
X20: 2027-03
J33: C · MIX DE MANTENIMIENTO — real vs meta (la meta se compara contra el % por HORAS)
J34: clase | K34: % real (horas) | L34: % meta | M34: desviación (pp) | N34: % real (conteo) | O34: horas | P34: órdenes
J35: predictivo | K35: =IF(N(IFERROR(INDEX(ADHERENCIA!$AA$134:$AA$151,MATCH($B$3,ADHERENCIA!$A$134:$A$151,0)),""))=0,"",$O35/IFERROR(INDEX(ADHERENCIA!$AA$134:$AA$151,MATCH($B$3,ADHERENCIA!$A$134:$A$151,0)),"")) | L35: =p_meta_pct_predictivo/100 | M35: =IF($K35="","",($K35-$L35)*100) | N35: =IF(N(IFERROR(INDEX(ADHERENCIA!$T$134:$T$151,MATCH($B$3,ADHERENCIA!$A$134:$A$151,0)),""))=0,"",$P35/IFERROR(INDEX(ADHERENCIA!$T$134:$T$151,MATCH($B$3,ADHERENCIA!$A$134:$A$151,0)),"")) | O35: =IFERROR(INDEX(ADHERENCIA!$V$134:$V$151,MATCH($B$3,ADHERENCIA!$A$134:$A$151,0)),"") | P35: =IFERROR(INDEX(ADHERENCIA!$O$134:$O$151,MATCH($B$3,ADHERENCIA!$A$134:$A$151,0)),"")
J36: preventivo | K36: =IF(N(IFERROR(INDEX(ADHERENCIA!$AA$134:$AA$151,MATCH($B$3,ADHERENCIA!$A$134:$A$151,0)),""))=0,"",$O36/IFERROR(INDEX(ADHERENCIA!$AA$134:$AA$151,MATCH($B$3,ADHERENCIA!$A$134:$A$151,0)),"")) | L36: =p_meta_pct_preventivo/100 | M36: =IF($K36="","",($K36-$L36)*100) | N36: =IF(N(IFERROR(INDEX(ADHERENCIA!$T$134:$T$151,MATCH($B$3,ADHERENCIA!$A$134:$A$151,0)),""))=0,"",$P36/IFERROR(INDEX(ADHERENCIA!$T$134:$T$151,MATCH($B$3,ADHERENCIA!$A$134:$A$151,0)),"")) | O36: =IFERROR(INDEX(ADHERENCIA!$W$134:$W$151,MATCH($B$3,ADHERENCIA!$A$134:$A$151,0)),"") | P36: =IFERROR(INDEX(ADHERENCIA!$P$134:$P$151,MATCH($B$3,ADHERENCIA!$A$134:$A$151,0)),"")
J37: correctivo_programado | K37: =IF(N(IFERROR(INDEX(ADHERENCIA!$AA$134:$AA$151,MATCH($B$3,ADHERENCIA!$A$134:$A$151,0)),""))=0,"",$O37/IFERROR(INDEX(ADHERENCIA!$AA$134:$AA$151,MATCH($B$3,ADHERENCIA!$A$134:$A$151,0)),"")) | L37: =p_meta_pct_correctivo_programado/100 | M37: =IF($K37="","",($K37-$L37)*100) | N37: =IF(N(IFERROR(INDEX(ADHERENCIA!$T$134:$T$151,MATCH($B$3,ADHERENCIA!$A$134:$A$151,0)),""))=0,"",$P37/IFERROR(INDEX(ADHERENCIA!$T$134:$T$151,MATCH($B$3,ADHERENCIA!$A$134:$A$151,0)),"")) | O37: =IFERROR(INDEX(ADHERENCIA!$X$134:$X$151,MATCH($B$3,ADHERENCIA!$A$134:$A$151,0)),"") | P37: =IFERROR(INDEX(ADHERENCIA!$Q$134:$Q$151,MATCH($B$3,ADHERENCIA!$A$134:$A$151,0)),"")
J38: emergencia | K38: =IF(N(IFERROR(INDEX(ADHERENCIA!$AA$134:$AA$151,MATCH($B$3,ADHERENCIA!$A$134:$A$151,0)),""))=0,"",$O38/IFERROR(INDEX(ADHERENCIA!$AA$134:$AA$151,MATCH($B$3,ADHERENCIA!$A$134:$A$151,0)),"")) | L38: =p_meta_pct_emergencia/100 | M38: =IF($K38="","",($K38-$L38)*100) | N38: =IF(N(IFERROR(INDEX(ADHERENCIA!$T$134:$T$151,MATCH($B$3,ADHERENCIA!$A$134:$A$151,0)),""))=0,"",$P38/IFERROR(INDEX(ADHERENCIA!$T$134:$T$151,MATCH($B$3,ADHERENCIA!$A$134:$A$151,0)),"")) | O38: =IFERROR(INDEX(ADHERENCIA!$Y$134:$Y$151,MATCH($B$3,ADHERENCIA!$A$134:$A$151,0)),"") | P38: =IFERROR(INDEX(ADHERENCIA!$R$134:$R$151,MATCH($B$3,ADHERENCIA!$A$134:$A$151,0)),"")
J39: SIN CLASIFICAR | K39: =IF(N(IFERROR(INDEX(ADHERENCIA!$AA$134:$AA$151,MATCH($B$3,ADHERENCIA!$A$134:$A$151,0)),""))=0,"",$O39/IFERROR(INDEX(ADHERENCIA!$AA$134:$AA$151,MATCH($B$3,ADHERENCIA!$A$134:$A$151,0)),"")) | L39: =0 | M39: =IF($K39="","",($K39-$L39)*100) | N39: =IF(N(IFERROR(INDEX(ADHERENCIA!$T$134:$T$151,MATCH($B$3,ADHERENCIA!$A$134:$A$151,0)),""))=0,"",$P39/IFERROR(INDEX(ADHERENCIA!$T$134:$T$151,MATCH($B$3,ADHERENCIA!$A$134:$A$151,0)),"")) | O39: =IFERROR(INDEX(ADHERENCIA!$Z$134:$Z$151,MATCH($B$3,ADHERENCIA!$A$134:$A$151,0)),"") | P39: =IFERROR(INDEX(ADHERENCIA!$S$134:$S$151,MATCH($B$3,ADHERENCIA!$A$134:$A$151,0)),"")
J40: TOTAL (control) | K40: =IF(N(IFERROR(INDEX(ADHERENCIA!$AA$134:$AA$151,MATCH($B$3,ADHERENCIA!$A$134:$A$151,0)),""))=0,"",SUM($K$35:$K$39)) | L40: =SUM($L$35:$L$39) | N40: =IF(N(IFERROR(INDEX(ADHERENCIA!$T$134:$T$151,MATCH($B$3,ADHERENCIA!$A$134:$A$151,0)),""))=0,"",SUM($N$35:$N$39)) | O40: =SUM($O$35:$O$39) | P40: =SUM($P$35:$P$39)
J41: DIFERENCIA vs el mes (debe ser 0) | O41: =ROUND($O40-N(IFERROR(INDEX(ADHERENCIA!$AA$134:$AA$151,MATCH($B$3,ADHERENCIA!$A$134:$A$151,0)),"")),6) | P41: =$P40-N(IFERROR(INDEX(ADHERENCIA!$T$134:$T$151,MATCH($B$3,ADHERENCIA!$A$134:$A$151,0)),""))
J42: =PARAMETROS!$B$29
J43: RUBRO (calibración, lubricación) es etiqueta transversal: NO entra en este mix, se mide en sus tarjetas.
A51: BLOQUES DE DATOS DE LOS GRÁFICOS — se leen de las hojas fuente y responden al mes seleccionado. No editar.
A52: A · cumplimiento semanal del mes elegido
A53: semana | B53: adherencia | C53: meta
A54: =IF((DATE(VALUE(LEFT($B$3,4)),VALUE(RIGHT($B$3,2)),1)-WEEKDAY(DATE(VALUE(LEFT($B$3,4)),VALUE(RIGHT($B$3,2)),1),2)+1+0)>DATE(VALUE(LEFT($B$3,4)),VALUE(RIGHT($B$3,2))+1,0),"",YEAR((DATE(VALUE(LEFT($B$3,4)),VALUE(RIGHT($B$3,2)),1)-WEEKDAY(DATE(VALUE(LEFT($B$3,4)),VALUE(RIGHT($B$3,2)),1),2)+1+0)+4-WEEKDAY((DATE(VALUE(LEFT($B$3,4)),VALUE(RIGHT($B$3,2)),1)-WEEKDAY(DATE(VALUE(LEFT($B$3,4)),VALUE(RIGHT($B$3,2)),1),2)+1+0),2))&"-S"&TEXT(_xlfn.ISOWEEKNUM((DATE(VALUE(LEFT($B$3,4)),VALUE(RIGHT($B$3,2)),1)-WEEKDAY(DATE(VALUE(LEFT($B$3,4)),VALUE(RIGHT($B$3,2)),1),2)+1+0)),"00")) | B54: =IF($A54="","",IFERROR(INDEX(ADHERENCIA!$D$5:$D$64,MATCH($A54,ADHERENCIA!$A$5:$A$64,0)),"")) | C54: =IF($A54="","",p_meta_adherencia)
A55: =IF((DATE(VALUE(LEFT($B$3,4)),VALUE(RIGHT($B$3,2)),1)-WEEKDAY(DATE(VALUE(LEFT($B$3,4)),VALUE(RIGHT($B$3,2)),1),2)+1+7)>DATE(VALUE(LEFT($B$3,4)),VALUE(RIGHT($B$3,2))+1,0),"",YEAR((DATE(VALUE(LEFT($B$3,4)),VALUE(RIGHT($B$3,2)),1)-WEEKDAY(DATE(VALUE(LEFT($B$3,4)),VALUE(RIGHT($B$3,2)),1),2)+1+7)+4-WEEKDAY((DATE(VALUE(LEFT($B$3,4)),VALUE(RIGHT($B$3,2)),1)-WEEKDAY(DATE(VALUE(LEFT($B$3,4)),VALUE(RIGHT($B$3,2)),1),2)+1+7),2))&"-S"&TEXT(_xlfn.ISOWEEKNUM((DATE(VALUE(LEFT($B$3,4)),VALUE(RIGHT($B$3,2)),1)-WEEKDAY(DATE(VALUE(LEFT($B$3,4)),VALUE(RIGHT($B$3,2)),1),2)+1+7)),"00")) | B55: =IF($A55="","",IFERROR(INDEX(ADHERENCIA!$D$5:$D$64,MATCH($A55,ADHERENCIA!$A$5:$A$64,0)),"")) | C55: =IF($A55="","",p_meta_adherencia)
A56: =IF((DATE(VALUE(LEFT($B$3,4)),VALUE(RIGHT($B$3,2)),1)-WEEKDAY(DATE(VALUE(LEFT($B$3,4)),VALUE(RIGHT($B$3,2)),1),2)+1+14)>DATE(VALUE(LEFT($B$3,4)),VALUE(RIGHT($B$3,2))+1,0),"",YEAR((DATE(VALUE(LEFT($B$3,4)),VALUE(RIGHT($B$3,2)),1)-WEEKDAY(DATE(VALUE(LEFT($B$3,4)),VALUE(RIGHT($B$3,2)),1),2)+1+14)+4-WEEKDAY((DATE(VALUE(LEFT($B$3,4)),VALUE(RIGHT($B$3,2)),1)-WEEKDAY(DATE(VALUE(LEFT($B$3,4)),VALUE(RIGHT($B$3,2)),1),2)+1+14),2))&"-S"&TEXT(_xlfn.ISOWEEKNUM((DATE(VALUE(LEFT($B$3,4)),VALUE(RIGHT($B$3,2)),1)-WEEKDAY(DATE(VALUE(LEFT($B$3,4)),VALUE(RIGHT($B$3,2)),1),2)+1+14)),"00")) | B56: =IF($A56="","",IFERROR(INDEX(ADHERENCIA!$D$5:$D$64,MATCH($A56,ADHERENCIA!$A$5:$A$64,0)),"")) | C56: =IF($A56="","",p_meta_adherencia)
A57: =IF((DATE(VALUE(LEFT($B$3,4)),VALUE(RIGHT($B$3,2)),1)-WEEKDAY(DATE(VALUE(LEFT($B$3,4)),VALUE(RIGHT($B$3,2)),1),2)+1+21)>DATE(VALUE(LEFT($B$3,4)),VALUE(RIGHT($B$3,2))+1,0),"",YEAR((DATE(VALUE(LEFT($B$3,4)),VALUE(RIGHT($B$3,2)),1)-WEEKDAY(DATE(VALUE(LEFT($B$3,4)),VALUE(RIGHT($B$3,2)),1),2)+1+21)+4-WEEKDAY((DATE(VALUE(LEFT($B$3,4)),VALUE(RIGHT($B$3,2)),1)-WEEKDAY(DATE(VALUE(LEFT($B$3,4)),VALUE(RIGHT($B$3,2)),1),2)+1+21),2))&"-S"&TEXT(_xlfn.ISOWEEKNUM((DATE(VALUE(LEFT($B$3,4)),VALUE(RIGHT($B$3,2)),1)-WEEKDAY(DATE(VALUE(LEFT($B$3,4)),VALUE(RIGHT($B$3,2)),1),2)+1+21)),"00")) | B57: =IF($A57="","",IFERROR(INDEX(ADHERENCIA!$D$5:$D$64,MATCH($A57,ADHERENCIA!$A$5:$A$64,0)),"")) | C57: =IF($A57="","",p_meta_adherencia)
A58: =IF((DATE(VALUE(LEFT($B$3,4)),VALUE(RIGHT($B$3,2)),1)-WEEKDAY(DATE(VALUE(LEFT($B$3,4)),VALUE(RIGHT($B$3,2)),1),2)+1+28)>DATE(VALUE(LEFT($B$3,4)),VALUE(RIGHT($B$3,2))+1,0),"",YEAR((DATE(VALUE(LEFT($B$3,4)),VALUE(RIGHT($B$3,2)),1)-WEEKDAY(DATE(VALUE(LEFT($B$3,4)),VALUE(RIGHT($B$3,2)),1),2)+1+28)+4-WEEKDAY((DATE(VALUE(LEFT($B$3,4)),VALUE(RIGHT($B$3,2)),1)-WEEKDAY(DATE(VALUE(LEFT($B$3,4)),VALUE(RIGHT($B$3,2)),1),2)+1+28),2))&"-S"&TEXT(_xlfn.ISOWEEKNUM((DATE(VALUE(LEFT($B$3,4)),VALUE(RIGHT($B$3,2)),1)-WEEKDAY(DATE(VALUE(LEFT($B$3,4)),VALUE(RIGHT($B$3,2)),1),2)+1+28)),"00")) | B58: =IF($A58="","",IFERROR(INDEX(ADHERENCIA!$D$5:$D$64,MATCH($A58,ADHERENCIA!$A$5:$A$64,0)),"")) | C58: =IF($A58="","",p_meta_adherencia)
A59: =IF((DATE(VALUE(LEFT($B$3,4)),VALUE(RIGHT($B$3,2)),1)-WEEKDAY(DATE(VALUE(LEFT($B$3,4)),VALUE(RIGHT($B$3,2)),1),2)+1+35)>DATE(VALUE(LEFT($B$3,4)),VALUE(RIGHT($B$3,2))+1,0),"",YEAR((DATE(VALUE(LEFT($B$3,4)),VALUE(RIGHT($B$3,2)),1)-WEEKDAY(DATE(VALUE(LEFT($B$3,4)),VALUE(RIGHT($B$3,2)),1),2)+1+35)+4-WEEKDAY((DATE(VALUE(LEFT($B$3,4)),VALUE(RIGHT($B$3,2)),1)-WEEKDAY(DATE(VALUE(LEFT($B$3,4)),VALUE(RIGHT($B$3,2)),1),2)+1+35),2))&"-S"&TEXT(_xlfn.ISOWEEKNUM((DATE(VALUE(LEFT($B$3,4)),VALUE(RIGHT($B$3,2)),1)-WEEKDAY(DATE(VALUE(LEFT($B$3,4)),VALUE(RIGHT($B$3,2)),1),2)+1+35)),"00")) | B59: =IF($A59="","",IFERROR(INDEX(ADHERENCIA!$D$5:$D$64,MATCH($A59,ADHERENCIA!$A$5:$A$64,0)),"")) | C59: =IF($A59="","",p_meta_adherencia)
...

Sheet INSTRUCTIVO
A1: INSTRUCTIVO — cómo se usa MantPlan
A2: =HYPERLINK("#DASHBOARD!A1","◂ VOLVER AL TABLERO")
A3: Versión 3.6.0 · generado 2026-07-27 · ARCHIVO DE PLANTILLA: trae 8 órdenes de EJEMPLO que hay que borrar.
A6: A. QUÉ ES Y QUÉ NO ES
A7: Sirve para PROGRAMAR y CONTROLAR la semana de mantenimiento: repartir el trabajo entre los técnicos, ver si la carga cabe en las horas disponibles, medir si se cumplió lo programado y seguir el gasto contra el presupuesto.
A8: NO genera órdenes de trabajo: las órdenes salen de su ERP/CMMS y se pegan aquí.
A9: NO sustituye al ERP/CMMS: no guarda historial, no cierra órdenes, no notifica.
A10: NO analiza confiabilidad: no calcula MTBF, MTTR ni criticidad (ver el punto G).
A11: NO gestiona almacén: no conoce stock, reservas ni consumo de repuestos.
A13: B. ANTES DE EMPEZAR — configuración, una sola vez
A14: 1. PARAMETROS — nombre de empresa y planta, moneda, horas de jornada, factor de productividad, metas de adherencia y de mix, y la fecha de datos.
A15: 2. Catálogos (hojas CAT_*, ocultas: clic derecho en una pestaña → Mostrar) — mapee los códigos de SU ERP: centros de costo, puestos de trabajo, actividades, tipos de OT, estados del ERP, supervisores y turnos. Es lo único que hay que traducir.
A16: 3. TECNICOS — reemplace el roster de ejemplo por su gente. `rotativo` = sí si entra al ciclo de turnos; `orden_rotacion` = su posición de arranque (1..N, sin repetir dentro de la misma especialidad y área); `activo` = no lo saca de las listas, de la capacidad y del ciclo sin borrarlo.
A17: 4. CALENDARIO — marque el patrón semanal y cargue feriados y paros de planta.
... A56: MOTOR: las 10 reglas de negocio viven en las fórmulas y no cambian entre empresas. CATÁLOGOS: lo que sí cambia. PARAMETROS: lo que se ajusta. Sin macros, sin enlaces externos y sin ningún código de empresa dentro de una fórmula: por eso adaptarlo a otra planta es editar catálogos, no programar. El detalle de cada decisión está en MANUAL.md, junto al archivo.

Sheet PLAN_SEMANAL
A1: PLAN SEMANAL — el gráfico de carga y la grilla responden a los mismos selectores. "(todos)" desactiva un criterio; "-" significa vacío.
A2: =HYPERLINK("#DASHBOARD!A1","◂ VOLVER AL TABLERO") | P2: datos del gráfico de carga — no editar | X2: semanas con datos (validación) — no editar
A3: semana: | B3: 2026-S31 | C3: día: | D3: (todos) | E3: turno: | F3: (todos) | G3: coordinador: | H3: (todos) | I3: área: | J3: (todos) | K3: especialidad: | L3: (todos) | M3: sub-área: | N3: (todos) | P3: tecnico | Q3: especialidad | R3: etiqueta | S3: hha_seleccion | T3: dentro_capacidad | U3: sobreasignacion | V3: capacidad | X3: (todos)
P4: Carlos Pérez | Q4: MEC | R4: =IF(OR($B$3="(todos)",$D$3="(todos)"),$P4,$P4&" ("&_xlfn.XLOOKUP($B$3&"|"&$D$3&"|"&$P4,tblAsignaciones[clave],tblAsignaciones[turno],"")&")") | S4: =IF(AND($L$3<>"(todos)",$Q4<>$L$3),NA(),SUMIFS(tblOrdenes[horas_efectivas],tblOrdenes[tecnico_asignado],$P4,tblOrdenes[semana],IF($B$3="(todos)","*",$B$3),tblOrdenes[dia_semana],IF($D$3="(todos)","*",$D$3),tblOrdenes[turno_asignado],IF($F$3="(todos)","*",$F$3),tblOrdenes[coordinador],IF($H$3="(todos)","*",$H$3),tblOrdenes[area],IF($J$3="(todos)","*",$J$3),tblOrdenes[sub_area],IF($N$3="(todos)","*",$N$3))) | T4: =IF(ISNA($S4),NA(),MIN($S4,$V4)) | U4: =IF(ISNA($S4),NA(),MAX(0,$S4-$V4)) | V4: =IF(AND($L$3<>"(todos)",$Q4<>$L$3),NA(),p_factor_productividad*SUMIFS(tblAsignaciones[horas_disponibles],tblAsignaciones[tecnico],$P4,tblAsignaciones[semana],IF($B$3="(todos)","*",$B$3),tblAsignaciones[dia],IF($D$3="(todos)","*",$D$3))) | X4: 2025-S51
A5: órdenes: | B5: =COUNTIFS($A$26:$A$1225,IF($B$3="(todos)","*",$B$3),$B$26:$B$1225,IF($D$3="(todos)","*",$D$3),$C$26:$C$1225,IF($F$3="(todos)","*",$F$3),$D$26:$D$1225,IF($H$3="(todos)","*",$H$3),$E$26:$E$1225,IF($J$3="(todos)","*",$J$3),$F$26:$F$1225,IF($L$3="(todos)","*",$L$3),$G$26:$G$1225,IF($N$3="(todos)","*",$N$3)) | C5: HH: | D5: =SUMIFS($L$26:$L$1225,$A$26:$A$1225,IF($B$3="(todos)","*",$B$3),$B$26:$B$1225,IF($D$3="(todos)","*",$D$3),$C$26:$C$1225,IF($F$3="(todos)","*",$F$3),$D$26:$D$1225,IF($H$3="(todos)","*",$H$3),$E$26:$E$1225,IF($J$3="(todos)","*",$J$3),$F$26:$F$1225,IF($L$3="(todos)","*",$L$3),$G$26:$G$1225,IF($N$3="(todos)","*",$N$3)) | P5: María Gómez | Q5: MEC | R5: =IF(OR($B$3="(todos)",$D$3="(todos)"),$P5,$P5&" ("&_xlfn.XLOOKUP($B$3&"|"&$D$3&"|"&$P5,tblAsignaciones[clave],tblAsignaciones[turno],"")&")") | S5: =IF(AND($L$3<>"(todos)",$Q5<>$L$3),NA(),SUMIFS(tblOrdenes[horas_efectivas],tblOrdenes[tecnico_asignado],$P5,tblOrdenes[semana],IF($B$3="(todos)","*",$B$3),tblOrdenes[dia_semana],IF($D$3="(todos)","*",$D$3),tblOrdenes[turno_asignado],IF($F$3="(todos)","*",$F$3),tblOrdenes[coordinador],IF($H$3="(todos)","*",$H$3),tblOrdenes[area],IF($J$3="(todos)","*",$J$3),tblOrdenes[sub_area],IF($N$3="(todos)","*",$N$3))) | T5: =IF(ISNA($S5),NA(),MIN($S5,$V5)) | U5: =IF(ISNA($S5),NA(),MAX(0,$S5-$V5)) | V5: =IF(AND($L$3<>"(todos)",$Q5<>$L$3),NA(),p_factor_productividad*SUMIFS(tblAsignaciones[horas_disponibles],tblAsignaciones[tecnico],$P5,tblAsignaciones[semana],IF($B$3="(todos)","*",$B$3),tblAsignaciones[dia],IF($D$3="(todos)","*",$D$3))) | X5: 2025-S52
P6: Luis Rodríguez | Q6: MEC | R6: =IF(OR($B$3="(todos)",$D$3="(todos)"),$P6,$P6&" ("&_xlfn.XLOOKUP($B$3&"|"&$D$3&"|"&$P6,tblAsignaciones[clave],tblAsignaciones[turno],"")&")") | S6: =IF(AND($L$3<>"(todos)",$Q6<>$L$3),NA(),SUMIFS(tblOrdenes[horas_efectivas],tblOrdenes[tecnico_asignado],$P6,tblOrdenes[semana],IF($B$3="(todos)","*",$B$3),tblOrdenes[dia_semana],IF($D$3="(todos)","*",$D$3),tblOrdenes[turno_asignado],IF($F$3="(todos)","*",$F$3),tblOrdenes[coordinador],IF($H$3="(todos)","*",$H$3),tblOrdenes[area],IF($J$3="(todos)","*",$J$3),tblOrdenes[sub_area],IF($N$3="(todos)","*",$N$3))) | T6: =IF(ISNA($S6),NA(),MIN($S6,$V6)) | U6: =IF(ISNA($S6),NA(),MAX(0,$S6-$V6)) | V6: =IF(AND($L$3<>"(todos)",$Q6<>$L$3),NA(),p_factor_productividad*SUMIFS(tblAsignaciones[horas_disponibles],tblAsignaciones[tecnico],$P6,tblAsignaciones[semana],IF($B$3="(todos)","*",$B$3),tblAsignaciones[dia],IF($D$3="(todos)","*",$D$3))) | X6: 2026-S01
P7: Miguel Martínez | Q7: MEC | R7: =IF(OR($B$3="(todos)",$D$3="(todos)"),$P7,$P7&" ("&_xlfn.XLOOKUP($B$3&"|"&$D$3&"|"&$P7,tblAsignaciones[clave],tblAsignaciones[turno],"")&")") | S7: =IF(AND($L$3<>"(todos)",$Q7<>$L$3),NA(),SUMIFS(tblOrdenes[horas_efectivas],tblOrdenes[tecnico_asignado],$P7,tblOrdenes[semana],IF($B$3="(todos)","*",$B$3),tblOrdenes[dia_semana],IF($D$3="(todos)","*",$D$3),tblOrdenes[turno_asignado],IF($F$3="(todos)","*",$F$3),tblOrdenes[coordinador],IF($H$3="(todos)","*",$H$3),tblOrdenes[area],IF($J$3="(todos)","*",$J$3),tblOrdenes[sub_area],IF($N$3="(todos)","*",$N$3))) | T7: =IF(ISNA($S7),NA(),MIN($S7,$V7)) | U7: =IF(ISNA($S7),NA(),MAX(0,$S7-$V7)) | V7: =IF(AND($L$3<>"(todos)",$Q7<>$L$3),NA(),p_factor_productividad*SUMIFS(tblAsignaciones[horas_disponibles],tblAsignaciones[tecnico],$P7,tblAsignaciones[semana],IF($B$3="(todos)","*",$B$3),tblAsignaciones[dia],IF($D$3="(todos)","*",$D$3))) | X7: 2026-S02
P8: Ana Sánchez | Q8: MEC | R8: =IF(OR($B$3="(todos)",$D$3="(todos)"),$P8,$P8&" ("&_xlfn.XLOOKUP($B$3&"|"&$D$3&"|"&$P8,tblAsignaciones[clave],tblAsignaciones[turno],"")&")") | S8: =IF(AND($L$3<>"(todos)",$Q8<>$L$3),NA(),SUMIFS(tblOrdenes[horas_efectivas],tblOrdenes[tecnico_asignado],$P8,tblOrdenes[semana],IF($B$3="(todos)","*",$B$3),tblOrdenes[dia_semana],IF($D$3="(todos)","*",$D$3),tblOrdenes[turno_asignado],IF($F$3="(todos)","*",$F$3),tblOrdenes[coordinador],IF($H$3="(todos)","*",$H$3),tblOrdenes[area],IF($J$3="(todos)","*",$J$3),tblOrdenes[sub_area],IF($N$3="(todos)","*",$N$3))) | T8: =IF(ISNA($S8),NA(),MIN($S8,$V8)) | U8: =IF(ISNA($S8),NA(),MAX(0,$S8-$V8)) | V8: =IF(AND($L$3<>"(todos)",$Q8<>$L$3),NA(),p_factor_productividad*SUMIFS(tblAsignaciones[horas_disponibles],tblAsignaciones[tecnico],$P8,tblAsignaciones[semana],IF($B$3="(todos)","*",$B$3),tblAsignaciones[dia],IF($D$3="(todos)","*",$D$3))) | X8: 2026-S03
P9: David Torres | Q9: MEC | R9: =IF(OR($B$3="(todos)",$D$3="(todos)"),$P9,$P9&" ("&_xlfn.XLOOKUP($B$3&"|"&$D$3&"|"&$P9,tblAsignaciones[clave],tblAsignaciones[turno],"")&")") | S9: =IF(AND($L$3<>"(todos)",$Q9<>$L$3),NA(),SUMIFS(tblOrdenes[horas_efectivas],tblOrdenes[tecnico_asignado],$P9,tblOrdenes[semana],IF($B$3="(todos)","*",$B$3),tblOrdenes[dia_semana],IF($D$3="(todos)","*",$D$3),tblOrdenes[turno_asignado],IF($F$3="(todos)","*",$F$3),tblOrdenes[coordinador],IF($H$3="(todos)","*",$H$3),tblOrdenes[area],IF($J$3="(todos)","*",$J$3),tblOrdenes[sub_area],IF($N$3="(todos)","*",$N$3))) | T9: =IF(ISNA($S9),NA(),MIN($S9,$V9)) | U9: =IF(ISNA($S9),NA(),MAX(0,$S9-$V9)) | V9: =IF(AND($L$3<>"(todos)",$Q9<>$L$3),NA(),p_factor_productividad*SUMIFS(tblAsignaciones[horas_disponibles],tblAsignaciones[tecnico],$P9,tblAsignaciones[semana],IF($B$3="(todos)","*",$B$3),tblAsignaciones[dia],IF($D$3="(todos)","*",$D$3))) | X9: 2026-S04
P10: Francisco Ramírez | Q10: MEC | R10: =IF(OR($B$3="(todos)",$D$3="(todos)"),$P10,$P10&" ("&_xlfn.XLOOKUP($B$3&"|"&$D$3&"|"&$P10,tblAsignaciones[clave],tblAsignaciones[turno],"")&")") | S10: =IF(AND($L$3<>"(todos)",$Q10<>$L$3),NA(),SUMIFS(tblOrdenes[horas_efectivas],tblOrdenes[tecnico_asignado],$P10,tblOrdenes[semana],IF($B$3="(todos)","*",$B$3),tblOrdenes[dia_semana],IF($D$3="(todos)","*",$D$3),tblOrdenes[turno_asignado],IF($F$3="(todos)","*",$F$3),tblOrdenes[coordinador],IF($H$3="(todos)","*",$H$3),tblOrdenes[area],IF($J$3="(todos)","*",$J$3),tblOrdenes[sub_area],IF($N$3="(todos)","*",$N$3))) | T10: =IF(ISNA($S10),NA(),MIN($S10,$V10)) | U10: =IF(ISNA($S10),NA(),MAX(0,$S10-$V10)) | V10: =IF(AND($L$3<>"(todos)",$Q10<>$L$3),NA(),p_factor_productividad*SUMIFS(tblAsignaciones[horas_disponibles],tblAsignaciones[tecnico],$P10,tblAsignaciones[semana],IF($B$3="(todos)","*",$B$3),tblAsignaciones[dia],IF($D$3="(todos)","*",$D$3))) | X10: 2026-S05
P11: Jorge Díaz | Q11: ELE | R11: =IF(OR($B$3="(todos)",$D$3="(todos)"),$P11,$P11&" ("&_xlfn.XLOOKUP($B$3&"|"&$D$3&"|"&$P11,tblAsignaciones[clave],tblAsignaciones[turno],"")&")") | S11: =IF(AND($L$3<>"(todos)",$Q11<>$L$3),NA(),SUMIFS(tblOrdenes[horas_efectivas],tblOrdenes[tecnico_asignado],$P11,tblOrdenes[semana],IF($B$3="(todos)","*",$B$3),tblOrdenes[dia_semana],IF($D$3="(todos)","*",$D$3),tblOrdenes[turno_asignado],IF($F$3="(todos)","*",$F$3),tblOrdenes[coordinador],IF($H$3="(todos)","*",$H$3),tblOrdenes[area],IF($J$3="(todos)","*",$J$3),tblOrdenes[sub_area],IF($N$3="(todos)","*",$N$3))) | T11: =IF(ISNA($S11),NA(),MIN($S11,$V11)) | U11: =IF(ISNA($S11),NA(),MAX(0,$S11-$V11)) | V11: =IF(AND($L$3<>"(todos)",$Q11<>$L$3),NA(),p_factor_productividad*SUMIFS(tblAsignaciones[horas_disponibles],tblAsignaciones[tecnico],$P11,tblAsignaciones[semana],IF($B$3="(todos)","*",$B$3),tblAsignaciones[dia],IF($D$3="(todos)","*",$D$3))) | X11: 2026-S06
P12: Roberto Castro | Q12: ELE | R12: =IF(OR($B$3="(todos)",$D$3="(todos)"),$P12,$P12&" ("&_xlfn.XLOOKUP($B$3&"|"&$D$3&"|"&$P12,tblAsignaciones[clave],tblAsignaciones[turno],"")&")") | S12: =IF(AND($L$3<>"(todos)",$Q12<>$L$3),NA(),SUMIFS(tblOrdenes[horas_efectivas],tblOrdenes[tecnico_asignado],$P12,tblOrdenes[semana],IF($B$3="(todos)","*",$B$3),tblOrdenes[dia_semana],IF($D$3="(todos)","*",$D$3),tblOrdenes[turno_asignado],IF($F$3="(todos)","*",$F$3),tblOrdenes[coordinador],IF($H$3="(todos)","*",$H$3),tblOrdenes[area],IF($J$3="(todos)","*",$J$3),tblOrdenes[sub_area],IF($N$3="(todos)","*",$N$3))) | T12: =IF(ISNA($S12),NA(),MIN($S12,$V12)) | U12: =IF(ISNA($S12),NA(),MAX(0,$S12-$V12)) | V12: =IF(AND($L$3<>"(todos)",$Q12<>$L$3),NA(),p_factor_productividad*SUMIFS(tblAsignaciones[horas_disponibles],tblAsignaciones[tecnico],$P12,tblAsignaciones[semana],IF($B$3="(todos)","*",$B$3),tblAsignaciones[dia],IF($D$3="(todos)","*",$D$3))) | X12: 2026-S07
P13: Laura Morales | Q13: ELE | R13: =IF(OR($B$3="(todos)",$D$3="(todos)"),$P13,$P13&" ("&_xlfn.XLOOKUP($B$3&"|"&$D$3&"|"&$P13,tblAsignaciones[clave],tblAsignaciones[turno],"")&")") | S13: =IF(AND($L$3<>"(todos)",$Q13<>$L$3),NA(),SUMIFS(tblOrdenes[horas_efectivas],tblOrdenes[tecnico_asignado],$P13,tblOrdenes[semana],IF($B$3="(todos)","*",$B$3),tblOrdenes[dia_semana],IF($D$3="(todos)","*",$D$3),tblOrdenes[turno_asignado],IF($F$3="(todos)","*",$F$3),tblOrdenes[coordinador],IF($H$3="(todos)","*",$H$3),tblOrdenes[area],IF($J$3="(todos)","*",$J$3),tblOrdenes[sub_area],IF($N$3="(todos)","*",$N$3))) | T13: =IF(ISNA($S13),NA(),MIN($S13,$V13)) | U13: =IF(ISNA($S13),NA(),MAX(0,$S13-$V13)) | V13: =IF(AND($L$3<>"(todos)",$Q13<>$L$3),NA(),p_factor_productividad*SUMIFS(tblAsignaciones[horas_disponibles],tblAsignaciones[tecnico],$P13,tblAsignaciones[semana],IF($B$3="(todos)","*",$B$3),tblAsignaciones[dia],IF($D$3="(todos)","*",$D$3))) | X13: 2026-S08
P14: Ricardo Ortiz | Q14: ELE | R14: =IF(OR($B$3="(todos)",$D$3="(todos)"),$P14,$P14&" ("&_xlfn.XLOOKUP($B$3&"|"&$D$3&"|"&$P14,tblAsignaciones[clave],tblAsignaciones[turno],"")&")") | S14: =IF(AND($L$3<>"(todos)",$Q14<>$L$3),NA(),SUMIFS(tblOrdenes[horas_efectivas],tblOrdenes[tecnico_asignado],$P14,tblOrdenes[semana],IF($B$3="(todos)","*",$B$3),tblOrdenes[dia_semana],IF($D$3="(todos)","*",$D$3),tblOrdenes[turno_asignado],IF($F$3="(todos)","*",$F$3),tblOrdenes[coordinador],IF($H$3="(todos)","*",$H$3),tblOrdenes[area],IF($J$3="(todos)","*",$J$3),tblOrdenes[sub_area],IF($N$3="(todos)","*",$N$3))) | T14: =IF(ISNA($S14),NA(),MIN($S14,$V14)) | U14: =IF(ISNA($S14),NA(),MAX(0,$S14-$V14)) | V14: =IF(AND($L$3<>"(todos)",$Q14<>$L$3),NA(),p_factor_productividad*SUMIFS(tblAsignaciones[horas_disponibles],tblAsignaciones[tecnico],$P14,tblAsignaciones[semana],IF($B$3="(todos)","*",$B$3),tblAsignaciones[dia],IF($D$3="(todos)","*",$D$3))) | X14: 2026-S09
P15: Eduardo Silva | Q15: ELE | R15: =IF(OR($B$3="(todos)",$D$3="(todos)"),$P15,$P15&" ("&_xlfn.XLOOKUP($B$3&"|"&$D$3&"|"&$P15,tblAsignaciones[clave],tblAsignaciones[turno],"")&")") | S15: =IF(AND($L$3<>"(todos)",$Q15<>$L$3),NA(),SUMIFS(tblOrdenes[horas_efectivas],tblOrdenes[tecnico_asignado],$P15,tblOrdenes[semana],IF($B$3="(todos)","*",$B$3),tblOrdenes[dia_semana],IF($D$3="(todos)","*",$D$3),tblOrdenes[turno_asignado],IF($F$3="(todos)","*",$F$3),tblOrdenes[coordinador],IF($H$3="(todos)","*",$H$3),tblOrdenes[area],IF($J$3="(todos)","*",$J$3),tblOrdenes[sub_area],IF($N$3="(todos)","*",$N$3))) | T15: =IF(ISNA($S15),NA(),MIN($S15,$V15)) | U15: =IF(ISNA($S15),NA(),MAX(0,$S15-$V15)) | V15: =IF(AND($L$3<>"(todos)",$Q15<>$L$3),NA(),p_factor_productividad*SUMIFS(tblAsignaciones[horas_disponibles],tblAsignaciones[tecnico],$P15,tblAsignaciones[semana],IF($B$3="(todos)","*",$B$3),tblAsignaciones[dia],IF($D$3="(todos)","*",$D$3))) | X15: 2026-S10
P16: Gabriela Rojas | Q16: ELE | R16: =IF(OR($B$3="(todos)",$D$3="(todos)"),$P16,$P16&" ("&_xlfn.XLOOKUP($B$3&"|"&$D$3&"|"&$P16,tblAsignaciones[clave],tblAsignaciones[turno],"")&")") | S16: =IF(AND($L$3<>"(todos)",$Q16<>$L$3),NA(),SUMIFS(tblOrdenes[horas_efectivas],tblOrdenes[tecnico_asignado],$P16,tblOrdenes[semana],IF($B$3="(todos)","*",$B$3),tblOrdenes[dia_semana],IF($D$3="(todos)","*",$D$3),tblOrdenes[turno_asignado],IF($F$3="(todos)","*",$F$3),tblOrdenes[coordinador],IF($H$3="(todos)","*",$H$3),tblOrdenes[area],IF($J$3="(todos)","*",$J$3),tblOrdenes[sub_area],IF($N$3="(todos)","*",$N$3))) | T16: =IF(ISNA($S16),NA(),MIN($S16,$V16)) | U16: =IF(ISNA($S16),NA(),MAX(0,$S16-$V16)) | V16: =IF(AND($L$3<>"(todos)",$Q16<>$L$3),NA(),p_factor_productividad*SUMIFS(tblAsignaciones[horas_disponibles],tblAsignaciones[tecnico],$P16,tblAsignaciones[semana],IF($B$3="(todos)","*",$B$3),tblAsignaciones[dia],IF($D$3="(todos)","*",$D$3))) | X16: 2026-S11
P17: Fernando Mendoza | Q17: ELE | R17: =IF(OR($B$3="(todos)",$D$3="(todos)"),$P17,$P17&" ("&_xlfn.XLOOKUP($B$3&"|"&$D$3&"|"&$P17,tblAsignaciones[clave],tblAsignaciones[turno],"")&")") | S17: =IF(AND($L$3<>"(todos)",$Q17<>$L$3),NA(),SUMIFS(tblOrdenes[horas_efectivas],tblOrdenes[tecnico_asignado],$P17,tblOrdenes[semana],IF($B$3="(todos)","*",$B$3),tblOrdenes[dia_semana],IF($D$3="(todos)","*",$D$3),tblOrdenes[turno_asignado],IF($F$3="(todos)","*",$F$3),tblOrdenes[coordinador],IF($H$3="(todos)","*",$H$3),tblOrdenes[area],IF($J$3="(todos)","*",$J$3),tblOrdenes[sub_area],IF($N$3="(todos)","*",$N$3))) | T17: =IF(ISNA($S17),NA(),MIN($S17,$V17)) | U17: =IF(ISNA($S17),NA(),MAX(0,$S17-$V17)) | V17: =IF(AND($L$3<>"(todos)",$Q17<>$L$3),NA(),p_factor_productividad*SUMIFS(tblAsignaciones[horas_disponibles],tblAsignaciones[tecnico],$P17,tblAsignaciones[semana],IF($B$3="(todos)","*",$B$3),tblAsignaciones[dia],IF($D$3="(todos)","*",$D$3))) | X17: 2026-S12
... P19: Daniela Medina | Q19: AUT | R19: =IF(OR($B$3="(todos)",$D$3="(todos)"),$P19,$P19&" ("&_xlfn.XLOOKUP($B$3&"|"&$D$3&"|"&$P19,tblAsignaciones[clave],tblAsignaciones[turno],"")&")") | S19: =IF(AND($L$3<>"(todos)",$Q19<>$L$3),NA(),SUMIFS(tblOrdenes[horas_efectivas],tblOrdenes[tecnico_asignado],$P19,tblOrdenes[semana],IF($B$3="(todos)","*",$B$3),tblOrdenes[dia_semana],IF($D$3="(todos)","*",$D$3),tblOrdenes[turno_asignado],IF($F$3="(todos)","*",$F$3),tblOrdenes[coordinador],IF($H$3="(todos)","*",$H$3),tblOrdenes[area],IF($J$3="(todos)","*",$J$3),tblOrdenes[sub_area],IF($N$3="(todos)","*",$N$3))) | T19: =IF(ISNA($S19),NA(),MIN($S19,$V19)) | U19: =IF(ISNA($S19),NA(),MAX(0,$S19-$V19)) | V19: =IF(AND($L$3<>"(todos)",$Q19<>$L$3),NA(),p_factor_productividad*SUMIFS(tblAsignaciones[horas_disponibles],tblAsignaciones[tecnico],$P19,tblAsignaciones[semana],IF($B$3="(todos)","*",$B$3),tblAsignaciones[dia],IF($D$3="(todos)","*",$D$3))) | X19: 2026-S14
X20: 2026-S15
X21: 2026-S16
X22: 2026-S17
X23: 2026-S18
X24: 2026-S19
A25: semana | B25: dia | C25: turno | D25: coordinador | E25: area | F25: especialidad | G25: sub_area | H25: tecnico | I25: id_operacion | J25: descripcion_operacion | K25: equipo | L25: horas | M25: estado | N25: en_plan | X25: 2026-S20
A26: =IF('ORDENES'!$A4="","",IF('ORDENES'!$O4="","-",'ORDENES'!$O4)) | B26: =IF('ORDENES'!$A4="","",IF('ORDENES'!$S4="","-",'ORDENES'!$S4)) | C26: =IF('ORDENES'!$A4="","",IF('ORDENES'!$AI4="","-",'ORDENES'!$AI4)) | D26: =IF('ORDENES'!$A4="","",IF('ORDENES'!$AA4="","-",'ORDENES'!$AA4)) | E26: =IF('ORDENES'!$A4="","",IF('ORDENES'!$Y4="","-",'ORDENES'!$Y4)) | F26: =IF('ORDENES'!$A4="","",IF('ORDENES'!$AB4="","-",'ORDENES'!$AB4)) | G26: =IF('ORDENES'!$A4="","",IF('ORDENES'!$Z4="","-",'ORDENES'!$Z4)) | H26: =IF('ORDENES'!$A4="","",IF('ORDENES'!$AH4="","-",'ORDENES'!$AH4)) | I26: =IF('ORDENES'!$A4="","",IF('ORDENES'!$AU4="","-",'ORDENES'!$AU4)) | J26: =IF('ORDENES'!$A4="","",IF('ORDENES'!$D4="","-",'ORDENES'!$D4)) | K26: =IF('ORDENES'!$A4="","",IF('ORDENES'!$E4="","-",'ORDENES'!$E4)) | L26: =IF('ORDENES'!$A4="","",IF('ORDENES'!$M4="",0,'ORDENES'!$M4)) | M26: =IF('ORDENES'!$A4="","",IF('ORDENES'!$N4="","-",'ORDENES'!$N4)) | N26: =IF('ORDENES'!$A4="","",'ORDENES'!$AG4) | X26: 2026-S21
A27: =IF('ORDENES'!$A5="","",IF('ORDENES'!$O5="","-",'ORDENES'!$O5)) | B27: =IF('ORDENES'!$A5="","",IF('ORDENES'!$S5="","-",'ORDENES'!$S5)) | C27: =IF('ORDENES'!$A5="","",IF('ORDENES'!$AI5="","-",'ORDENES'!$AI5)) | D27: =IF('ORDENES'!$A5="","",IF('ORDENES'!$AA5="","-",'ORDENES'!$AA5)) | E27: =IF('ORDENES'!$A5="","",IF('ORDENES'!$Y5="","-",'ORDENES'!$Y5)) | F27: =IF('ORDENES'!$A5="","",IF('ORDENES'!$AB5="","-",'ORDENES'!$AB5)) | G27: =IF('ORDENES'!$A5="","",IF('ORDENES'!$Z5="","-",'ORDENES'!$Z5)) | H27: =IF('ORDENES'!$A5="","",IF('ORDENES'!$AH5="","-",'ORDENES'!$AH5)) | I27: =IF('ORDENES'!$A5="","",IF('ORDENES'!$AU5="","-",'ORDENES'!$AU5)) | J27: =IF('ORDENES'!$A5="","",IF('ORDENES'!$D5="","-",'ORDENES'!$D5)) | K27: =IF('ORDENES'!$A5="","",IF('ORDENES'!$E5="","-",'ORDENES'!$E5)) | L27: =IF('ORDENES'!$A5="","",IF('ORDENES'!$M5="",0,'ORDENES'!$M5)) | M27: =IF('ORDENES'!$A5="","",IF('ORDENES'!$N5="","-",'ORDENES'!$N5)) | N27: =IF('ORDENES'!$A5="","",'ORDENES'!$AG5) | X27: 2026-S22
A28: =IF('ORDENES'!$A6="","",IF('ORDENES'!$O6="","-",'ORDENES'!$O6)) | B28: =IF('ORDENES'!$A6="","",IF('ORDENES'!$S6="","-",'ORDENES'!$S6)) | C28: =IF('ORDENES'!$A6="","",IF('ORDENES'!$AI6="","-",'ORDENES'!$AI6)) | D28: =IF('ORDENES'!$A6="","",IF('ORDENES'!$AA6="","-",'ORDENES'!$AA6)) | E28: =IF('ORDENES'!$A6="","",IF('ORDENES'!$Y6="","-",'ORDENES'!$Y6)) | F28: =IF('ORDENES'!$A6="","",IF('ORDENES'!$AB6="","-",'ORDENES'!$AB6)) | G28: =IF('ORDENES'!$A6="","",IF('ORDENES'!$Z6="","-",'ORDENES'!$Z6)) | H28: =IF('ORDENES'!$A6="","",IF('ORDENES'!$AH6="","-",'ORDENES'!$AH6)) | I28: =IF('ORDENES'!$A6="","",IF('ORDENES'!$AU6="","-",'ORDENES'!$AU6)) | J28: =IF('ORDENES'!$A6="","",IF('ORDENES'!$D6="","-",'ORDENES'!$D6)) | K28: =IF('ORDENES'!$A6="","",IF('ORDENES'!$E6="","-",'ORDENES'!$E6)) | L28: =IF('ORDENES'!$A6="","",IF('ORDENES'!$M6="",0,'ORDENES'!$M6)) | M28: =IF('ORDENES'!$A6="","",IF('ORDENES'!$N6="","-",'ORDENES'!$N6)) | N28: =IF('ORDENES'!$A6="","",'ORDENES'!$AG6) | X28: 2026-S23
A29: =IF('ORDENES'!$A7="","",IF('ORDENES'!$O7="","-",'ORDENES'!$O7)) | B29: =IF('ORDENES'!$A7="","",IF('ORDENES'!$S7="","-",'ORDENES'!$S7)) | C29: =IF('ORDENES'!$A7="","",IF('ORDENES'!$AI7="","-",'ORDENES'!$AI7)) | D29: =IF('ORDENES'!$A7="","",IF('ORDENES'!$AA7="","-",'ORDENES'!$AA7)) | E29: =IF('ORDENES'!$A7="","",IF('ORDENES'!$Y7="","-",'ORDENES'!$Y7)) | F29: =IF('ORDENES'!$A7="","",IF('ORDENES'!$AB7="","-",'ORDENES'!$AB7)) | G29: =IF('ORDENES'!$A7="","",IF('ORDENES'!$Z7="","-",'ORDENES'!$Z7)) | H29: =IF('ORDENES'!$A7="","",IF('ORDENES'!$AH7="","-",'ORDENES'!$AH7)) | I29: =IF('ORDENES'!$A7="","",IF('ORDENES'!$AU7="","-",'ORDENES'!$AU7)) | J29: =IF('ORDENES'!$A7="","",IF('ORDENES'!$D7="","-",'ORDENES'!$D7)) | K29: =IF('ORDENES'!$A7="","",IF('ORDENES'!$E7="","-",'ORDENES'!$E7)) | L29: =IF('ORDENES'!$A7="","",IF('ORDENES'!$M7="",0,'ORDENES'!$M7)) | M29: =IF('ORDENES'!$A7="","",IF('ORDENES'!$N7="","-",'ORDENES'!$N7)) | N29: =IF('ORDENES'!$A7="","",'ORDENES'!$AG7) | X29: 2026-S24
A30: =IF('ORDENES'!$A8="","",IF('ORDENES'!$O8="","-",'ORDENES'!$O8)) | B30: =IF('ORDENES'!$A8="","",IF('ORDENES'!$S8="","-",'ORDENES'!$S8)) | C30: =IF('ORDENES'!$A8="","",IF('ORDENES'!$AI8="","-",'ORDENES'!$AI8)) | D30: =IF('ORDENES'!$A8="","",IF('ORDENES'!$AA8="","-",'ORDENES'!$AA8)) | E30: =IF('ORDENES'!$A8="","",IF('ORDENES'!$Y8="","-",'ORDENES'!$Y8)) | F30: =IF('ORDENES'!$A8="","",IF('ORDENES'!$AB8="","-",'ORDENES'!$AB8)) | G30: =IF('ORDENES'!$A8="","",IF('ORDENES'!$Z8="","-",'ORDENES'!$Z8)) | H30: =IF('ORDENES'!$A8="","",IF('ORDENES'!$AH8="","-",'ORDENES'!$AH8)) | I30: =IF('ORDENES'!$A8="","",IF('ORDENES'!$AU8="","-",'ORDENES'!$AU8)) | J30: =IF('ORDENES'!$A8="","",IF('ORDENES'!$D8="","-",'ORDENES'!$D8)) | K30: =IF('ORDENES'!$A8="","",IF('ORDENES'!$E8="","-",'ORDENES'!$E8)) | L30: =IF('ORDENES'!$A8="","",IF('ORDENES'!$M8="",0,'ORDENES'!$M8)) | M30: =IF('ORDENES'!$A8="","",IF('ORDENES'!$N8="","-",'ORDENES'!$N8)) | N30: =IF('ORDENES'!$A8="","",'ORDENES'!$AG8) | X30: 2026-S25
A31: =IF('ORDENES'!$A9="","",IF('ORDENES'!$O9="","-",'ORDENES'!$O9)) | B31: =IF('ORDENES'!$A9="","",IF('ORDENES'!$S9="","-",'ORDENES'!$S9)) | C31: =IF('ORDENES'!$A9="","",IF('ORDENES'!$AI9="","-",'ORDENES'!$AI9)) | D31: =IF('ORDENES'!$A9="","",IF('ORDENES'!$AA9="","-",'ORDENES'!$AA9)) | E31: =IF('ORDENES'!$A9="","",IF('ORDENES'!$Y9="","-",'ORDENES'!$Y9)) | F31: =IF('ORDENES'!$A9="","",IF('ORDENES'!$AB9="","-",'ORDENES'!$AB9)) | G31: =IF('ORDENES'!$A9="","",IF('ORDENES'!$Z9="","-",'ORDENES'!$Z9)) | H31: =IF('ORDENES'!$A9="","",IF('ORDENES'!$AH9="","-",'ORDENES'!$AH9)) | I31: =IF('ORDENES'!$A9="","",IF('ORDENES'!$AU9="","-",'ORDENES'!$AU9)) | J31: =IF('ORDENES'!$A9="","",IF('ORDENES'!$D9="","-",'ORDENES'!$D9)) | K31: =IF('ORDENES'!$A9="","",IF('ORDENES'!$E9="","-",'ORDENES'!$E9)) | L31: =IF('ORDENES'!$A9="","",IF('ORDENES'!$M9="",0,'ORDENES'!$M9)) | M31: =IF('ORDENES'!$A9="","",IF('ORDENES'!$N9="","-",'ORDENES'!$N9)) | N31: =IF('ORDENES'!$A9="","",'ORDENES'!$AG9) | X31: 2026-S26
A32: =IF('ORDENES'!$A10="","",IF('ORDENES'!$O10="","-",'ORDENES'!$O10)) | B32: =IF('ORDENES'!$A10="","",IF('ORDENES'!$S10="","-",'ORDENES'!$S10)) | C32: =IF('ORDENES'!$A10="","",IF('ORDENES'!$AI10="","-",'ORDENES'!$AI10)) | D32: =IF('ORDENES'!$A10="","",IF('ORDENES'!$AA10="","-",'ORDENES'!$AA10)) | E32: =IF('ORDENES'!$A10="","",IF('ORDENES'!$Y10="","-",'ORDENES'!$Y10)) | F32: =IF('ORDENES'!$A10="","",IF('ORDENES'!$AB10="","-",'ORDENES'!$AB10)) | G32: =IF('ORDENES'!$A10="","",IF('ORDENES'!$Z10="","-",'ORDENES'!$Z10)) | H32: =IF('ORDENES'!$A10="","",IF('ORDENES'!$AH10="","-",'ORDENES'!$AH10)) | I32: =IF('ORDENES'!$A10="","",IF('ORDENES'!$AU10="","-",'ORDENES'!$AU10)) | J32: =IF('ORDENES'!$A10="","",IF('ORDENES'!$D10="","-",'ORDENES'!$D10)) | K32: =IF('ORDENES'!$A10="","",IF('ORDENES'!$E10="","-",'ORDENES'!$E10)) | L32: =IF('ORDENES'!$A10="","",IF('ORDENES'!$M10="",0,'ORDENES'!$M10)) | M32: =IF('ORDENES'!$A10="","",IF('ORDENES'!$N10="","-",'ORDENES'!$N10)) | N32: =IF('ORDENES'!$A10="","",'ORDENES'!$AG10) | X32: 2026-S27
A33: =IF('ORDENES'!$A11="","",IF('ORDENES'!$O11="","-",'ORDENES'!$O11)) | B33: =IF('ORDENES'!$A11="","",IF('ORDENES'!$S11="","-",'ORDENES'!$S11)) | C33: =IF('ORDENES'!$A11="","",IF('ORDENES'!$AI11="","-",'ORDENES'!$AI11)) | D33: =IF('ORDENES'!$A11="","",IF('ORDENES'!$AA11="","-",'ORDENES'!$AA11)) | E33: =IF('ORDENES'!$A11="","",IF('ORDENES'!$Y11="","-",'ORDENES'!$Y11)) | F33: =IF('ORDENES'!$A11="","",IF('ORDENES'!$AB11="","-",'ORDENES'!$AB11)) | G33: =IF('ORDENES'!$A11="","",IF('ORDENES'!$Z11="","-",'ORDENES'!$Z11)) | H33: =IF('ORDENES'!$A11="","",IF('ORDENES'!$AH11="","-",'ORDENES'!$AH11)) | I33: =IF('ORDENES'!$A11="","",IF('ORDENES'!$AU11="","-",'ORDENES'!$AU11)) | J33: =IF('ORDENES'!$A11="","",IF('ORDENES'!$D11="","-",'ORDENES'!$D11)) | K33: =IF('ORDENES'!$A11="","",IF('ORDENES'!$E11="","-",'ORDENES'!$E11)) | L33: =IF('ORDENES'!$A11="","",IF('ORDENES'!$M11="",0,'ORDENES'!$M11)) | M33: =IF('ORDENES'!$A11="","",IF('ORDENES'!$N11="","-",'ORDENES'!$N11)) | N33: =IF('ORDENES'!$A11="","",'ORDENES'!$AG11) | X33: 2026-S28
A34: =IF('ORDENES'!$A12="","",IF('ORDENES'!$O12="","-",'ORDENES'!$O12)) | B34: =IF('ORDENES'!$A12="","",IF('ORDENES'!$S12="","-",'ORDENES'!$S12)) | C34: =IF('ORDENES'!$A12="","",IF('ORDENES'!$AI12="","-",'ORDENES'!$AI12)) | D34: =IF('ORDENES'!$A12="","",IF('ORDENES'!$AA12="","-",'ORDENES'!$AA12)) | E34: =IF('ORDENES'!$A12="","",IF('ORDENES'!$Y12="","-",'ORDENES'!$Y12)) | F34: =IF('ORDENES'!$A12="","",IF('ORDENES'!$AB12="","-",'ORDENES'!$AB12)) | G34: =IF('ORDENES'!$A12="","",IF('ORDENES'!$Z12="","-",'ORDENES'!$Z12)) | H34: =IF('ORDENES'!$A12="","",IF('ORDENES'!$AH12="","-",'ORDENES'!$AH12)) | I34: =IF('ORDENES'!$A12="","",IF('ORDENES'!$AU12="","-",'ORDENES'!$AU12)) | J34: =IF('ORDENES'!$A12="","",IF('ORDENES'!$D12="","-",'ORDENES'!$D12)) | K34: =IF('ORDENES'!$A12="","",IF('ORDENES'!$E12="","-",'ORDENES'!$E12)) | L34: =IF('ORDENES'!$A12="","",IF('ORDENES'!$M12="",0,'ORDENES'!$M12)) | M34: =IF('ORDENES'!$A12="","",IF('ORDENES'!$N12="","-",'ORDENES'!$N12)) | N34: =IF('ORDENES'!$A12="","",'ORDENES'!$AG12) | X34: 2026-S29
A35: =IF('ORDENES'!$A13="","",IF('ORDENES'!$O13="","-",'ORDENES'!$O13)) | B35: =IF('ORDENES'!$A13="","",IF('ORDENES'!$S13="","-",'ORDENES'!$S13)) | C35: =IF('ORDENES'!$A13="","",IF('ORDENES'!$AI13="","-",'ORDENES'!$AI13)) | D35: =IF('ORDENES'!$A13="","",IF('ORDENES'!$AA13="","-",'ORDENES'!$AA13)) | E35: =IF('ORDENES'!$A13="","",IF('ORDENES'!$Y13="","-",'ORDENES'!$Y13)) | F35: =IF('ORDENES'!$A13="","",IF('ORDENES'!$AB13="","-",'ORDENES'!$AB13)) | G35: =IF('ORDENES'!$A13="","",IF('ORDENES'!$Z13="","-",'ORDENES'!$Z13)) | H35: =IF('ORDENES'!$A13="","",IF('ORDENES'!$AH13="","-",'ORDENES'!$AH13)) | I35: =IF('ORDENES'!$A13="","",IF('ORDENES'!$AU13="","-",'ORDENES'!$AU13)) | J35: =IF('ORDENES'!$A13="","",IF('ORDENES'!$D13="","-",'ORDENES'!$D13)) | K35: =IF('ORDENES'!$A13="","",IF('ORDENES'!$E13="","-",'ORDENES'!$E13)) | L35: =IF('ORDENES'!$A13="","",IF('ORDENES'!$M13="",0,'ORDENES'!$M13)) | M35: =IF('ORDENES'!$A13="","",IF('ORDENES'!$N13="","-",'ORDENES'!$N13)) | N35: =IF('ORDENES'!$A13="","",'ORDENES'!$AG13) | X35: 2026-S30
A36: =IF('ORDENES'!$A14="","",IF('ORDENES'!$O14="","-",'ORDENES'!$O14)) | B36: =IF('ORDENES'!$A14="","",IF('ORDENES'!$S14="","-",'ORDENES'!$S14)) | C36: =IF('ORDENES'!$A14="","",IF('ORDENES'!$AI14="","-",'ORDENES'!$AI14)) | D36: =IF('ORDENES'!$A14="","",IF('ORDENES'!$AA14="","-",'ORDENES'!$AA14)) | E36: =IF('ORDENES'!$A14="","",IF('ORDENES'!$Y14="","-",'ORDENES'!$Y14)) | F36: =IF('ORDENES'!$A14="","",IF('ORDENES'!$AB14="","-",'ORDENES'!$AB14)) | G36: =IF('ORDENES'!$A14="","",IF('ORDENES'!$Z14="","-",'ORDENES'!$Z14)) | H36: =IF('ORDENES'!$A14="","",IF('ORDENES'!$AH14="","-",'ORDENES'!$AH14)) | I36: =IF('ORDENES'!$A14="","",IF('ORDENES'!$AU14="","-",'ORDENES'!$AU14)) | J36: =IF('ORDENES'!$A14="","",IF('ORDENES'!$D14="","-",'ORDENES'!$D14)) | K36: =IF('ORDENES'!$A14="","",IF('ORDENES'!$E14="","-",'ORDENES'!$E14)) | L36: =IF('ORDENES'!$A14="","",IF('ORDENES'!$M14="",0,'ORDENES'!$M14)) | M36: =IF('ORDENES'!$A14="","",IF('ORDENES'!$N14="","-",'ORDENES'!$N14)) | N36: =IF('ORDENES'!$A14="","",'ORDENES'!$AG14) | X36: 2026-S31
A37: =IF('ORDENES'!$A15="","",IF('ORDENES'!$O15="","-",'ORDENES'!$O15)) | B37: =IF('ORDENES'!$A15="","",IF('ORDENES'!$S15="","-",'ORDENES'!$S15)) | C37: =IF('ORDENES'!$A15="","",IF('ORDENES'!$AI15="","-",'ORDENES'!$AI15)) | D37: =IF('ORDENES'!$A15="","",IF('ORDENES'!$AA15="","-",'ORDENES'!$AA15)) | E37: =IF('ORDENES'!$A15="","",IF('ORDENES'!$Y15="","-",'ORDENES'!$Y15)) | F37: =IF('ORDENES'!$A15="","",IF('ORDENES'!$AB15="","-",'ORDENES'!$AB15)) | G37: =IF('ORDENES'!$A15="","",IF('ORDENES'!$Z15="","-",'ORDENES'!$Z15)) | H37: =IF('ORDENES'!$A15="","",IF('ORDENES'!$AH15="","-",'ORDENES'!$AH15)) | I37: =IF('ORDENES'!$A15="","",IF('ORDENES'!$AU15="","-",'ORDENES'!$AU15)) | J37: =IF('ORDENES'!$A15="","",IF('ORDENES'!$D15="","-",'ORDENES'!$D15)) | K37: =IF('ORDENES'!$A15="","",IF('ORDENES'!$E15="","-",'ORDENES'!$E15)) | L37: =IF('ORDENES'!$A15="","",IF('ORDENES'!$M15="",0,'ORDENES'!$M15)) | M37: =IF('ORDENES'!$A15="","",IF('ORDENES'!$N15="","-",'ORDENES'!$N15)) | N37: =IF('ORDENES'!$A15="","",'ORDENES'!$AG15) | X37: 2026-S32
... A60: =IF('ORDENES'!$A38="","",IF('ORDENES'!$O38="","-",'ORDENES'!$O38)) | B60: =IF('ORDENES'!$A38="","",IF('ORDENES'!$S38="","-",'ORDENES'!$S38)) | C60: =IF('ORDENES'!$A38="","",IF('ORDENES'!$AI38="","-",'ORDENES'!$AI38)) | D60: =IF('ORDENES'!$A38="","",IF('ORDENES'!$AA38="","-",'ORDENES'!$AA38)) | E60: =IF('ORDENES'!$A38="","",IF('ORDENES'!$Y38="","-",'ORDENES'!$Y38)) | F60: =IF('ORDENES'!$A38="","",IF('ORDENES'!$AB38="","-",'ORDENES'!$AB38)) | G60: =IF('ORDENES'!$A38="","",IF('ORDENES'!$Z38="","-",'ORDENES'!$Z38)) | H60: =IF('ORDENES'!$A38="","",IF('ORDENES'!$AH38="","-",'ORDENES'!$AH38)) | I60: =IF('ORDENES'!$A38="","",IF('ORDENES'!$AU38="","-",'ORDENES'!$AU38)) | J60: =IF('ORDENES'!$A38="","",IF('ORDENES'!$D38="","-",'ORDENES'!$D38)) | K60: =IF('ORDENES'!$A38="","",IF('ORDENES'!$E38="","-",'ORDENES'!$E38)) | L60: =IF('ORDENES'!$A38="","",IF('ORDENES'!$M38="",0,'ORDENES'!$M38)) | M60: =IF('ORDENES'!$A38="","",IF('ORDENES'!$N38="","-",'ORDENES'!$N38)) | N60: =IF('ORDENES'!$A38="","",'ORDENES'!$AG38) | X60: 2027-S02
A61: =IF('ORDENES'!$A39="","",IF('ORDENES'!$O39="","-",'ORDENES'!$O39)) | B61: =IF('ORDENES'!$A39="","",IF('ORDENES'!$S39="","-",'ORDENES'!$S39)) | C61: =IF('ORDENES'!$A39="","",IF('ORDENES'!$AI39="","-",'ORDENES'!$AI39)) | D61: =IF('ORDENES'!$A39="","",IF('ORDENES'!$AA39="","-",'ORDENES'!$AA39)) | E61: =IF('ORDENES'!$A39="","",IF('ORDENES'!$Y39="","-",'ORDENES'!$Y39)) | F61: =IF('ORDENES'!$A39="","",IF('ORDENES'!$AB39="","-",'ORDENES'!$AB39)) | G61: =IF('ORDENES'!$A39="","",IF('ORDENES'!$Z39="","-",'ORDENES'!$Z39)) | H61: =IF('ORDENES'!$A39="","",IF('ORDENES'!$AH39="","-",'ORDENES'!$AH39)) | I61: =IF('ORDENES'!$A39="","",IF('ORDENES'!$AU39="","-",'ORDENES'!$AU39)) | J61: =IF('ORDENES'!$A39="","",IF('ORDENES'!$D39="","-",'ORDENES'!$D39)) | K61: =IF('ORDENES'!$A39="","",IF('ORDENES'!$E39="","-",'ORDENES'!$E39)) | L61: =IF('ORDENES'!$A39="","",IF('ORDENES'!$M39="",0,'ORDENES'!$M39)) | M61: =IF('ORDENES'!$A39="","",IF('ORDENES'!$N39="","-",'ORDENES'!$N39)) | N61: =IF('ORDENES'!$A39="","",'ORDENES'!$AG39)
A62: =IF('ORDENES'!$A40="","",IF('ORDENES'!$O40="","-",'ORDENES'!$O40)) | B62: =IF('ORDENES'!$A40="","",IF('ORDENES'!$S40="","-",'ORDENES'!$S40)) | C62: =IF('ORDENES'!$A40="","",IF('ORDENES'!$AI40="","-",'ORDENES'!$AI40)) | D62: =IF('ORDENES'!$A40="","",IF('ORDENES'!$AA40="","-",'ORDENES'!$AA40)) | E62: =IF('ORDENES'!$A40="","",IF('ORDENES'!$Y40="","-",'ORDENES'!$Y40)) | F62: =IF('ORDENES'!$A40="","",IF('ORDENES'!$AB40="","-",'ORDENES'!$AB40)) | G62: =IF('ORDENES'!$A40="","",IF('ORDENES'!$Z40="","-",'ORDENES'!$Z40)) | H62: =IF('ORDENES'!$A40="","",IF('ORDENES'!$AH40="","-",'ORDENES'!$AH40)) | I62: =IF('ORDENES'!$A40="","",IF('ORDENES'!$AU40="","-",'ORDENES'!$AU40)) | J62: =IF('ORDENES'!$A40="","",IF('ORDENES'!$D40="","-",'ORDENES'!$D40)) | K62: =IF('ORDENES'!$A40="","",IF('ORDENES'!$E40="","-",'ORDENES'!$E40)) | L62: =IF('ORDENES'!$A40="","",IF('ORDENES'!$M40="",0,'ORDENES'!$M40)) | M62: =IF('ORDENES'!$A40="","",IF('ORDENES'!$N40="","-",'ORDENES'!$N40)) | N62: =IF('ORDENES'!$A40="","",'ORDENES'!$AG40)
A63: =IF('ORDENES'!$A41="","",IF('ORDENES'!$O41="","-",'ORDENES'!$O41)) | B63: =IF('ORDENES'!$A41="","",IF('ORDENES'!$S41="","-",'ORDENES'!$S41)) | C63: =IF('ORDENES'!$A41="","",IF('ORDENES'!$AI41="","-",'ORDENES'!$AI41)) | D63: =IF('ORDENES'!$A41="","",IF('ORDENES'!$AA41="","-",'ORDENES'!$AA41)) | E63: =IF('ORDENES'!$A41="","",IF('ORDENES'!$Y41="","-",'ORDENES'!$Y41)) | F63: =IF('ORDENES'!$A41="","",IF('ORDENES'!$AB41="","-",'ORDENES'!$AB41)) | G63: =IF('ORDENES'!$A41="","",IF('ORDENES'!$Z41="","-",'ORDENES'!$Z41)) | H63: =IF('ORDENES'!$A41="","",IF('ORDENES'!$AH41="","-",'ORDENES'!$AH41)) | I63: =IF('ORDENES'!$A41="","",IF('ORDENES'!$AU41="","-",'ORDENES'!$AU41)) | J63: =IF('ORDENES'!$A41="","",IF('ORDENES'!$D41="","-",'ORDENES'!$D41)) | K63: =IF('ORDENES'!$A41="","",IF('ORDENES'!$E41="","-",'ORDENES'!$E41)) | L63: =IF('ORDENES'!$A41="","",IF('ORDENES'!$M41="",0,'ORDENES'!$M41)) | M63: =IF('ORDENES'!$A41="","",IF('ORDENES'!$N41="","-",'ORDENES'!$N41)) | N63: =IF('ORDENES'!$A41="","",'ORDENES'!$AG41)
...

Sheet ADHERENCIA
A1: ADHERENCIA (REGLA-7) — rojo < 90 %, amarillo 90–95 %, verde > 95 %. Solo días hábiles: las órdenes en día no laborable no penalizan (se reportan en VALIDACION).
A2: =HYPERLINK("#DASHBOARD!A1","◂ VOLVER AL TABLERO")
A3: POR SEMANA (serie derivada de los datos, hasta 60)
A4: valor | B4: total_ot | C4: cerradas | D4: adherencia_conteo | E4: hh_total | F4: hh_cerradas | G4: adherencia_horas | H4: meta
A5: ='PERFIL_HH'!$O$4 | B5: =COUNTIFS(tblOrdenes[semana],$A5,tblOrdenes[es_habil],"sí") | C5: =COUNTIFS(tblOrdenes[semana],$A5,tblOrdenes[estado],"Cerrada",tblOrdenes[es_habil],"sí") | D5: =IF(B5=0,"",C5/B5) | E5: =SUMIFS(tblOrdenes[horas_efectivas],tblOrdenes[semana],$A5,tblOrdenes[es_habil],"sí") | F5: =SUMIFS(tblOrdenes[horas_efectivas],tblOrdenes[semana],$A5,tblOrdenes[estado],"Cerrada",tblOrdenes[es_habil],"sí") | G5: =IF(E5=0,"",F5/E5) | H5: =p_meta_adherencia
A6: ='PERFIL_HH'!$O$5 | B6: =COUNTIFS(tblOrdenes[semana],$A6,tblOrdenes[es_habil],"sí") | C6: =COUNTIFS(tblOrdenes[semana],$A6,tblOrdenes[estado],"Cerrada",tblOrdenes[es_habil],"sí") | D6: =IF(B6=0,"",C6/B6) | E6: =SUMIFS(tblOrdenes[horas_efectivas],tblOrdenes[semana],$A6,tblOrdenes[es_habil],"sí") | F6: =SUMIFS(tblOrdenes[horas_efectivas],tblOrdenes[semana],$A6,tblOrdenes[estado],"Cerrada",tblOrdenes[es_habil],"sí") | G6: =IF(E6=0,"",F6/E6) | H6: =p_meta_adherencia
A7: ='PERFIL_HH'!$O$6 | B7: =COUNTIFS(tblOrdenes[semana],$A7,tblOrdenes[es_habil],"sí") | C7: =COUNTIFS(tblOrdenes[semana],$A7,tblOrdenes[estado],"Cerrada",tblOrdenes[es_habil],"sí") | D7: =IF(B7=0,"",C7/B7) | E7: =SUMIFS(tblOrdenes[horas_efectivas],tblOrdenes[semana],$A7,tblOrdenes[es_habil],"sí") | F7: =SUMIFS(tblOrdenes[horas_efectivas],tblOrdenes[semana],$A7,tblOrdenes[estado],"Cerrada",tblOrdenes[es_habil],"sí") | G7: =IF(E7=0,"",F7/E7) | H7: =p_meta_adherencia
A8: ='PERFIL_HH'!$O$7 | B8: =COUNTIFS(tblOrdenes[semana],$A8,tblOrdenes[es_habil],"sí") | C8: =COUNTIFS(tblOrdenes[semana],$A8,tblOrdenes[estado],"Cerrada",tblOrdenes[es_habil],"sí") | D8: =IF(B8=0,"",C8/B8) | E8: =SUMIFS(tblOrdenes[horas_efectivas],tblOrdenes[semana],$A8,tblOrdenes[es_habil],"sí") | F8: =SUMIFS(tblOrdenes[horas_efectivas],tblOrdenes[semana],$A8,tblOrdenes[estado],"Cerrada",tblOrdenes[es_habil],"sí") | G8: =IF(E8=0,"",F8/E8) | H8: =p_meta_adherencia
A9: ='PERFIL_HH'!$O$8 | B9: =COUNTIFS(tblOrdenes[semana],$A9,tblOrdenes[es_habil],"sí") | C9: =COUNTIFS(tblOrdenes[semana],$A9,tblOrdenes[estado],"Cerrada",tblOrdenes[es_habil],"sí") | D9: =IF(B9=0,"",C9/B9) | E9: =SUMIFS(tblOrdenes[horas_efectivas],tblOrdenes[semana],$A9,tblOrdenes[es_habil],"sí") | F9: =SUMIFS(tblOrdenes[horas_efectivas],tblOrdenes[semana],$A9,tblOrdenes[estado],"Cerrada",tblOrdenes[es_habil],"sí") | G9: =IF(E9=0,"",F9/E9) | H9: =p_meta_adherencia
A10: ='PERFIL_HH'!$O$9 | B10: =COUNTIFS(tblOrdenes[semana],$A10,tblOrdenes[es_habil],"sí") | C10: =COUNTIFS(tblOrdenes[semana],$A10,tblOrdenes[estado],"Cerrada",tblOrdenes[es_habil],"sí") | D10: =IF(B10=0,"",C10/B10) | E10: =SUMIFS(tblOrdenes[horas_efectivas],tblOrdenes[semana],$A10,tblOrdenes[es_habil],"sí") | F10: =SUMIFS(tblOrdenes[horas_efectivas],tblOrdenes[semana],$A10,tblOrdenes[estado],"Cerrada",tblOrdenes[es_habil],"sí") | G10: =IF(E10=0,"",F10/E10) | H10: =p_meta_adherencia
A11: ='PERFIL_HH'!$O$10 | B11: =COUNTIFS(tblOrdenes[semana],$A11,tblOrdenes[es_habil],"sí") | C11: =COUNTIFS(tblOrdenes[semana],$A11,tblOrdenes[estado],"Cerrada",tblOrdenes[es_habil],"sí") | D11: =IF(B11=0,"",C11/B11) | E11: =SUMIFS(tblOrdenes[horas_efectivas],tblOrdenes[semana],$A11,tblOrdenes[es_habil],"sí") | F11: =SUMIFS(tblOrdenes[horas_efectivas],tblOrdenes[semana],$A11,tblOrdenes[estado],"Cerrada",tblOrdenes[es_habil],"sí") | G11: =IF(E11=0,"",F11/E11) | H11: =p_meta_adherencia
A12: ='PERFIL_HH'!$O$11 | B12: =COUNTIFS(tblOrdenes[semana],$A12,tblOrdenes[es_habil],"sí") | C12: =COUNTIFS(tblOrdenes[semana],$A12,tblOrdenes[estado],"Cerrada",tblOrdenes[es_habil],"sí") | D12: =IF(B12=0,"",C12/B12) | E12: =SUMIFS(tblOrdenes[horas_efectivas],tblOrdenes[semana],$A12,tblOrdenes[es_habil],"sí") | F12: =SUMIFS(tblOrdenes[horas_efectivas],tblOrdenes[semana],$A12,tblOrdenes[estado],"Cerrada",tblOrdenes[es_habil],"sí") | G12: =IF(E12=0,"",F12/E12) | H12: =p_meta_adherencia
A13: ='PERFIL_HH'!$O$12 | B13: =COUNTIFS(tblOrdenes[semana],$A13,tblOrdenes[es_habil],"sí") | C13: =COUNTIFS(tblOrdenes[semana],$A13,tblOrdenes[estado],"Cerrada",tblOrdenes[es_habil],"sí") | D13: =IF(B13=0,"",C13/B13) | E13: =SUMIFS(tblOrdenes[horas_efectivas],tblOrdenes[semana],$A13,tblOrdenes[es_habil],"sí") | F13: =SUMIFS(tblOrdenes[horas_efectivas],tblOrdenes[semana],$A13,tblOrdenes[estado],"Cerrada",tblOrdenes[es_habil],"sí") | G13: =IF(E13=0,"",F13/E13) | H13: =p_meta_adherencia
A14: ='PERFIL_HH'!$O$13 | B14: =COUNTIFS(tblOrdenes[semana],$A14,tblOrdenes[es_habil],"sí") | C14: =COUNTIFS(tblOrdenes[semana],$A14,tblOrdenes[estado],"Cerrada",tblOrdenes[es_habil],"sí") | D14: =IF(B14=0,"",C14/B14) | E14: =SUMIFS(tblOrdenes[horas_efectivas],tblOrdenes[semana],$A14,tblOrdenes[es_habil],"sí") | F14: =SUMIFS(tblOrdenes[horas_efectivas],tblOrdenes[semana],$A14,tblOrdenes[estado],"Cerrada",tblOrdenes[es_habil],"sí") | G14: =IF(E14=0,"",F14/E14) | H14: =p_meta_adherencia
A15: ='PERFIL_HH'!$O$14 | B15: =COUNTIFS(tblOrdenes[semana],$A15,tblOrdenes[es_habil],"sí") | C15: =COUNTIFS(tblOrdenes[semana],$A15,tblOrdenes[estado],"Cerrada",tblOrdenes[es_habil],"sí") | D15: =IF(B15=0,"",C15/B15) | E15: =SUMIFS(tblOrdenes[horas_efectivas],tblOrdenes[semana],$A15,tblOrdenes[es_habil],"sí") | F15: =SUMIFS(tblOrdenes[horas_efectivas],tblOrdenes[semana],$A15,tblOrdenes[estado],"Cerrada",tblOrdenes[es_habil],"sí") | G15: =IF(E15=0,"",F15/E15) | H15: =p_meta_adherencia
A16: ='PERFIL_HH'!$O$15 | B16: =COUNTIFS(tblOrdenes[semana],$A16,tblOrdenes[es_habil],"sí") | C16: =COUNTIFS(tblOrdenes[semana],$A16,tblOrdenes[estado],"Cerrada",tblOrdenes[es_habil],"sí") | D16: =IF(B16=0,"",C16/B16) | E16: =SUMIFS(tblOrdenes[horas_efectivas],tblOrdenes[semana],$A16,tblOrdenes[es_habil],"sí") | F16: =SUMIFS(tblOrdenes[horas_efectivas],tblOrdenes[semana],$A16,tblOrdenes[estado],"Cerrada",tblOrdenes[es_habil],"sí") | G16: =IF(E16=0,"",F16/E16) | H16: =p_meta_adherencia
A17: ='PERFIL_HH'!$O$16 | B17: =COUNTIFS(tblOrdenes[semana],$A17,tblOrdenes[es_habil],"sí") | C17: =COUNTIFS(tblOrdenes[semana],$A17,tblOrdenes[estado],"Cerrada",tblOrdenes[es_habil],"sí") | D17: =IF(B17=0,"",C17/B17) | E17: =SUMIFS(tblOrdenes[horas_efectivas],tblOrdenes[semana],$A17,tblOrdenes[es_habil],"sí") | F17: =SUMIFS(tblOrdenes[horas_efectivas],tblOrdenes[semana],$A17,tblOrdenes[estado],"Cerrada",tblOrdenes[es_habil],"sí") | G17: =IF(E17=0,"",F17/E17) | H17: =p_meta_adherencia
A18: ='PERFIL_HH'!$O$17 | B18: =COUNTIFS(tblOrdenes[semana],$A18,tblOrdenes[es_habil],"sí") | C18: =COUNTIFS(tblOrdenes[semana],$A18,tblOrdenes[estado],"Cerrada",tblOrdenes[es_habil],"sí") | D18: =IF(B18=0,"",C18/B18) | E18: =SUMIFS(tblOrdenes[horas_efectivas],tblOrdenes[semana],$A18,tblOrdenes[es_habil],"sí") | F18: =SUMIFS(tblOrdenes[horas_efectivas],tblOrdenes[semana],$A18,tblOrdenes[estado],"Cerrada",tblOrdenes[es_habil],"sí") | G18: =IF(E18=0,"",F18/E18) | H18: =p_meta_adherencia
A19: ='PERFIL_HH'!$O$18 | B19: =COUNTIFS(tblOrdenes[semana],$A19,tblOrdenes[es_habil],"sí") | C19: =COUNTIFS(tblOrdenes[semana],$A19,tblOrdenes[estado],"Cerrada",tblOrdenes[es_habil],"sí") | D19: =IF(B19=0,"",C19/B19) | E19: =SUMIFS(tblOrdenes[horas_efectivas],tblOrdenes[semana],$A19,tblOrdenes[es_habil],"sí") | F19: =SUMIFS(tblOrdenes[horas_efectivas],tblOrdenes[semana],$A19,tblOrdenes[estado],"Cerrada",tblOrdenes[es_habil],"sí") | G19: =IF(E19=0,"",F19/E19) | H19: =p_meta_adherencia
A20: ='PERFIL_HH'!$O$19 | B20: =COUNTIFS(tblOrdenes[semana],$A20,tblOrdenes[es_habil],"sí") | C20: =COUNTIFS(tblOrdenes[semana],$A20,tblOrdenes[estado],"Cerrada",tblOrdenes[es_habil],"sí") | D20: =IF(B20=0,"",C20/B20) | E20: =SUMIFS(tblOrdenes[horas_efectivas],tblOrdenes[semana],$A20,tblOrdenes[es_habil],"sí") | F20: =SUMIFS(tblOrdenes[horas_efectivas],tblOrdenes[semana],$A20,tblOrdenes[estado],"Cerrada",tblOrdenes[es_habil],"sí") | G20: =IF(E20=0,"",F20/E20) | H20: =p_meta_adherencia
A21: ='PERFIL_HH'!$O$20 | B21: =COUNTIFS(tblOrdenes[semana],$A21,tblOrdenes[es_habil],"sí") | C21: =COUNTIFS(tblOrdenes[semana],$A21,tblOrdenes[estado],"Cerrada",tblOrdenes[es_habil],"sí") | D21: =IF(B21=0,"",C21/B21) | E21: =SUMIFS(tblOrdenes[horas_efectivas],tblOrdenes[semana],$A21,tblOrdenes[es_habil],"sí") | F21: =SUMIFS(tblOrdenes[horas_efectivas],tblOrdenes[semana],$A21,tblOrdenes[estado],"Cerrada",tblOrdenes[es_habil],"sí") | G21: =IF(E21=0,"",F21/E21) | H21: =p_meta_adherencia
A22: ='PERFIL_HH'!$O$21 | B22: =COUNTIFS(tblOrdenes[semana],$A22,tblOrdenes[es_habil],"sí") | C22: =COUNTIFS(tblOrdenes[semana],$A22,tblOrdenes[estado],"Cerrada",tblOrdenes[es_habil],"sí") | D22: =IF(B22=0,"",C22/B22) | E22: =SUMIFS(tblOrdenes[horas_efectivas],tblOrdenes[semana],$A22,tblOrdenes[es_habil],"sí") | F22: =SUMIFS(tblOrdenes[horas_efectivas],tblOrdenes[semana],$A22,tblOrdenes[estado],"Cerrada",tblOrdenes[es_habil],"sí") | G22: =IF(E22=0,"",F22/E22) | H22: =p_meta_adherencia
A23: ='PERFIL_HH'!$O$22 | B23: =COUNTIFS(tblOrdenes[semana],$A23,tblOrdenes[es_habil],"sí") | C23: =COUNTIFS(tblOrdenes[semana],$A23,tblOrdenes[estado],"Cerrada",tblOrdenes[es_habil],"sí") | D23: =IF(B23=0,"",C23/B23) | E23: =SUMIFS(tblOrdenes[horas_efectivas],tblOrdenes[semana],$A23,tblOrdenes[es_habil],"sí") | F23: =SUMIFS(tblOrdenes[horas_efectivas],tblOrdenes[semana],$A23,tblOrdenes[estado],"Cerrada",tblOrdenes[es_habil],"sí") | G23: =IF(E23=0,"",F23/E23) | H23: =p_meta_adherencia
A24: ='PERFIL_HH'!$O$23 | B24: =COUNTIFS(tblOrdenes[semana],$A24,tblOrdenes[es_habil],"sí") | C24: =COUNTIFS(tblOrdenes[semana],$A24,tblOrdenes[estado],"Cerrada",tblOrdenes[es_habil],"sí") | D24: =IF(B24=0,"",C24/B24) | E24: =SUMIFS(tblOrdenes[horas_efectivas],tblOrdenes[semana],$A24,tblOrdenes[es_habil],"sí") | F24: =SUMIFS(tblOrdenes[horas_efectivas],tblOrdenes[semana],$A24,tblOrdenes[estado],"Cerrada",tblOrdenes[es_habil],"sí") | G24: =IF(E24=0,"",F24/E24) | H24: =p_meta_adherencia
A25: ='PERFIL_HH'!$O$24 | B25: =COUNTIFS(tblOrdenes[semana],$A25,tblOrdenes[es_habil],"sí") | C25: =COUNTIFS(tblOrdenes[semana],$A25,tblOrdenes[estado],"Cerrada",tblOrdenes[es_habil],"sí") | D25: =IF(B25=0,"",C25/B25) | E25: =SUMIFS(tblOrdenes[horas_efectivas],tblOrdenes[semana],$A25,tblOrdenes[es_habil],"sí") | F25: =SUMIFS(tblOrdenes[horas_efectivas],tblOrdenes[semana],$A25,tblOrdenes[estado],"Cerrada",tblOrdenes[es_habil],"sí") | G25: =IF(E25=0,"",F25/E25) | H25: =p_meta_adherencia
